[2025-01-26T18:42:25.655+0000] {local_task_job_runner.py:123} INFO - ::group::Pre task execution logs
[2025-01-26T18:42:25.679+0000] {taskinstance.py:2613} INFO - Dependencies all met for dep_context=non-requeueable deps ti=<TaskInstance: simulative_example_basic_dag.read_data_from_faker_api_and_load_to_pg.read_data_from_faker_api scheduled__2025-01-25T00:00:00+00:00 [queued]>
[2025-01-26T18:42:25.691+0000] {taskinstance.py:2613} INFO - Dependencies all met for dep_context=requeueable deps ti=<TaskInstance: simulative_example_basic_dag.read_data_from_faker_api_and_load_to_pg.read_data_from_faker_api scheduled__2025-01-25T00:00:00+00:00 [queued]>
[2025-01-26T18:42:25.693+0000] {taskinstance.py:2866} INFO - Starting attempt 1 of 1
[2025-01-26T18:42:25.710+0000] {taskinstance.py:2889} INFO - Executing <Task(_PythonDecoratedOperator): read_data_from_faker_api_and_load_to_pg.read_data_from_faker_api> on 2025-01-25 00:00:00+00:00
[2025-01-26T18:42:25.718+0000] {warnings.py:112} WARNING - /home/***/.local/lib/python3.12/site-packages/***/task/task_runner/standard_task_runner.py:70: DeprecationWarning: This process (pid=68) is multi-threaded, use of fork() may lead to deadlocks in the child.
  pid = os.fork()

[2025-01-26T18:42:25.719+0000] {standard_task_runner.py:72} INFO - Started process 86 to run task
[2025-01-26T18:42:25.723+0000] {standard_task_runner.py:104} INFO - Running: ['***', 'tasks', 'run', 'simulative_example_basic_dag', 'read_data_from_faker_api_and_load_to_pg.read_data_from_faker_api', 'scheduled__2025-01-25T00:00:00+00:00', '--job-id', '4', '--raw', '--subdir', 'DAGS_FOLDER/simulative_example_basic_dag.py', '--cfg-path', '/tmp/tmpdlikpqsl']
[2025-01-26T18:42:25.725+0000] {standard_task_runner.py:105} INFO - Job 4: Subtask read_data_from_faker_api_and_load_to_pg.read_data_from_faker_api
[2025-01-26T18:42:25.823+0000] {task_command.py:467} INFO - Running <TaskInstance: simulative_example_basic_dag.read_data_from_faker_api_and_load_to_pg.read_data_from_faker_api scheduled__2025-01-25T00:00:00+00:00 [running]> on host 3cfc25a6c20c
[2025-01-26T18:42:27.534+0000] {taskinstance.py:3132} INFO - Exporting env vars: AIRFLOW_CTX_DAG_OWNER='***' AIRFLOW_CTX_DAG_ID='simulative_example_basic_dag' AIRFLOW_CTX_TASK_ID='read_data_from_faker_api_and_load_to_pg.read_data_from_faker_api' AIRFLOW_CTX_EXECUTION_DATE='2025-01-25T00:00:00+00:00' AIRFLOW_CTX_TRY_NUMBER='1' AIRFLOW_CTX_DAG_RUN_ID='scheduled__2025-01-25T00:00:00+00:00'
[2025-01-26T18:42:27.536+0000] {logging_mixin.py:190} INFO - Task instance is in running state
[2025-01-26T18:42:27.540+0000] {logging_mixin.py:190} INFO -  Previous state of the Task instance: queued
[2025-01-26T18:42:27.544+0000] {logging_mixin.py:190} INFO - Current task name:read_data_from_faker_api_and_load_to_pg.read_data_from_faker_api state:running start_date:2025-01-26 18:42:25.681763+00:00
[2025-01-26T18:42:27.545+0000] {logging_mixin.py:190} INFO - Dag name:simulative_example_basic_dag and current dag run status:running
[2025-01-26T18:42:27.546+0000] {taskinstance.py:731} INFO - ::endgroup::
[2025-01-26T18:42:27.586+0000] {taskinstance.py:3311} ERROR - Task failed with exception
Traceback (most recent call last):
  File "/home/airflow/.local/lib/python3.12/site-packages/airflow/models/taskinstance.py", line 767, in _execute_task
    result = _execute_callable(context=context, **execute_callable_kwargs)
             ^^^^^^^^^^^^^^^^^^^^^^^^^^^^^^^^^^^^^^^^^^^^^^^^^^^^^^^^^^^^^
  File "/home/airflow/.local/lib/python3.12/site-packages/airflow/models/taskinstance.py", line 733, in _execute_callable
    return ExecutionCallableRunner(
           ^^^^^^^^^^^^^^^^^^^^^^^^
  File "/home/airflow/.local/lib/python3.12/site-packages/airflow/utils/operator_helpers.py", line 252, in run
    return self.func(*args, **kwargs)
           ^^^^^^^^^^^^^^^^^^^^^^^^^^
  File "/home/airflow/.local/lib/python3.12/site-packages/airflow/models/baseoperator.py", line 422, in wrapper
    return func(self, *args, **kwargs)
           ^^^^^^^^^^^^^^^^^^^^^^^^^^^
  File "/home/airflow/.local/lib/python3.12/site-packages/airflow/decorators/base.py", line 266, in execute
    return_value = super().execute(context)
                   ^^^^^^^^^^^^^^^^^^^^^^^^
  File "/home/airflow/.local/lib/python3.12/site-packages/airflow/models/baseoperator.py", line 422, in wrapper
    return func(self, *args, **kwargs)
           ^^^^^^^^^^^^^^^^^^^^^^^^^^^
  File "/home/airflow/.local/lib/python3.12/site-packages/airflow/operators/python.py", line 238, in execute
    return_value = self.execute_callable()
                   ^^^^^^^^^^^^^^^^^^^^^^^
  File "/home/airflow/.local/lib/python3.12/site-packages/airflow/operators/python.py", line 256, in execute_callable
    return runner.run(*self.op_args, **self.op_kwargs)
           ^^^^^^^^^^^^^^^^^^^^^^^^^^^^^^^^^^^^^^^^^^^
  File "/home/airflow/.local/lib/python3.12/site-packages/airflow/utils/operator_helpers.py", line 252, in run
    return self.func(*args, **kwargs)
           ^^^^^^^^^^^^^^^^^^^^^^^^^^
  File "/opt/airflow/dags/simulative_example_basic_dag.py", line 25, in read_data_from_faker_api
    faker_api_conn = BaseHook.get_connection("faker_api")
                     ^^^^^^^^^^^^^^^^^^^^^^^^^^^^^^^^^^^^
  File "/home/airflow/.local/lib/python3.12/site-packages/airflow/hooks/base.py", line 83, in get_connection
    conn = Connection.get_connection_from_secrets(conn_id)
           ^^^^^^^^^^^^^^^^^^^^^^^^^^^^^^^^^^^^^^^^^^^^^^^
  File "/home/airflow/.local/lib/python3.12/site-packages/airflow/models/connection.py", line 537, in get_connection_from_secrets
    raise AirflowNotFoundException(f"The conn_id `{conn_id}` isn't defined")
airflow.exceptions.AirflowNotFoundException: The conn_id `faker_api` isn't defined
[2025-01-26T18:42:27.601+0000] {logging_mixin.py:190} INFO - Task instance in failure state
[2025-01-26T18:42:27.602+0000] {logging_mixin.py:190} INFO - Task start:2025-01-26 18:42:25.681763+00:00 end:2025-01-26 18:42:27.601488+00:00 duration:1.919725
[2025-01-26T18:42:27.602+0000] {logging_mixin.py:190} INFO - Task:<Task(_PythonDecoratedOperator): read_data_from_faker_api_and_load_to_pg.read_data_from_faker_api> dag:<DAG: simulative_example_basic_dag> dagrun:<DagRun simulative_example_basic_dag @ 2025-01-25 00:00:00+00:00: scheduled__2025-01-25T00:00:00+00:00, state:running, queued_at: 2025-01-26 18:42:18.367876+00:00. externally triggered: False>
[2025-01-26T18:42:27.603+0000] {logging_mixin.py:190} INFO - Failure caused by The conn_id `faker_api` isn't defined
[2025-01-26T18:42:27.603+0000] {taskinstance.py:1225} INFO - Marking task as FAILED. dag_id=simulative_example_basic_dag, task_id=read_data_from_faker_api_and_load_to_pg.read_data_from_faker_api, run_id=scheduled__2025-01-25T00:00:00+00:00, execution_date=20250125T000000, start_date=20250126T184225, end_date=20250126T184227
[2025-01-26T18:42:27.615+0000] {taskinstance.py:340} INFO - ::group::Post task execution logs
[2025-01-26T18:42:27.616+0000] {standard_task_runner.py:124} ERROR - Failed to execute job 4 for task read_data_from_faker_api_and_load_to_pg.read_data_from_faker_api (The conn_id `faker_api` isn't defined; 86)
Traceback (most recent call last):
  File "/home/airflow/.local/lib/python3.12/site-packages/airflow/task/task_runner/standard_task_runner.py", line 117, in _start_by_fork
    ret = args.func(args, dag=self.dag)
          ^^^^^^^^^^^^^^^^^^^^^^^^^^^^^
  File "/home/airflow/.local/lib/python3.12/site-packages/airflow/cli/cli_config.py", line 49, in command
    return func(*args, **kwargs)
           ^^^^^^^^^^^^^^^^^^^^^
  File "/home/airflow/.local/lib/python3.12/site-packages/airflow/utils/cli.py", line 116, in wrapper
    return f(*args, **kwargs)
           ^^^^^^^^^^^^^^^^^^
  File "/home/airflow/.local/lib/python3.12/site-packages/airflow/cli/commands/task_command.py", line 483, in task_run
    task_return_code = _run_task_by_selected_method(args, _dag, ti)
                       ^^^^^^^^^^^^^^^^^^^^^^^^^^^^^^^^^^^^^^^^^^^^
  File "/home/airflow/.local/lib/python3.12/site-packages/airflow/cli/commands/task_command.py", line 256, in _run_task_by_selected_method
    return _run_raw_task(args, ti)
           ^^^^^^^^^^^^^^^^^^^^^^^
  File "/home/airflow/.local/lib/python3.12/site-packages/airflow/cli/commands/task_command.py", line 341, in _run_raw_task
    return ti._run_raw_task(
           ^^^^^^^^^^^^^^^^^
  File "/home/airflow/.local/lib/python3.12/site-packages/airflow/utils/session.py", line 97, in wrapper
    return func(*args, session=session, **kwargs)
           ^^^^^^^^^^^^^^^^^^^^^^^^^^^^^^^^^^^^^^
  File "/home/airflow/.local/lib/python3.12/site-packages/airflow/models/taskinstance.py", line 3005, in _run_raw_task
    return _run_raw_task(
           ^^^^^^^^^^^^^^
  File "/home/airflow/.local/lib/python3.12/site-packages/airflow/models/taskinstance.py", line 273, in _run_raw_task
    TaskInstance._execute_task_with_callbacks(
  File "/home/airflow/.local/lib/python3.12/site-packages/airflow/models/taskinstance.py", line 3159, in _execute_task_with_callbacks
    result = self._execute_task(context, task_orig)
             ^^^^^^^^^^^^^^^^^^^^^^^^^^^^^^^^^^^^^^
  File "/home/airflow/.local/lib/python3.12/site-packages/airflow/models/taskinstance.py", line 3183, in _execute_task
    return _execute_task(self, context, task_orig)
           ^^^^^^^^^^^^^^^^^^^^^^^^^^^^^^^^^^^^^^^
  File "/home/airflow/.local/lib/python3.12/site-packages/airflow/models/taskinstance.py", line 767, in _execute_task
    result = _execute_callable(context=context, **execute_callable_kwargs)
             ^^^^^^^^^^^^^^^^^^^^^^^^^^^^^^^^^^^^^^^^^^^^^^^^^^^^^^^^^^^^^
  File "/home/airflow/.local/lib/python3.12/site-packages/airflow/models/taskinstance.py", line 733, in _execute_callable
    return ExecutionCallableRunner(
           ^^^^^^^^^^^^^^^^^^^^^^^^
  File "/home/airflow/.local/lib/python3.12/site-packages/airflow/utils/operator_helpers.py", line 252, in run
    return self.func(*args, **kwargs)
           ^^^^^^^^^^^^^^^^^^^^^^^^^^
  File "/home/airflow/.local/lib/python3.12/site-packages/airflow/models/baseoperator.py", line 422, in wrapper
    return func(self, *args, **kwargs)
           ^^^^^^^^^^^^^^^^^^^^^^^^^^^
  File "/home/airflow/.local/lib/python3.12/site-packages/airflow/decorators/base.py", line 266, in execute
    return_value = super().execute(context)
                   ^^^^^^^^^^^^^^^^^^^^^^^^
  File "/home/airflow/.local/lib/python3.12/site-packages/airflow/models/baseoperator.py", line 422, in wrapper
    return func(self, *args, **kwargs)
           ^^^^^^^^^^^^^^^^^^^^^^^^^^^
  File "/home/airflow/.local/lib/python3.12/site-packages/airflow/operators/python.py", line 238, in execute
    return_value = self.execute_callable()
                   ^^^^^^^^^^^^^^^^^^^^^^^
  File "/home/airflow/.local/lib/python3.12/site-packages/airflow/operators/python.py", line 256, in execute_callable
    return runner.run(*self.op_args, **self.op_kwargs)
           ^^^^^^^^^^^^^^^^^^^^^^^^^^^^^^^^^^^^^^^^^^^
  File "/home/airflow/.local/lib/python3.12/site-packages/airflow/utils/operator_helpers.py", line 252, in run
    return self.func(*args, **kwargs)
           ^^^^^^^^^^^^^^^^^^^^^^^^^^
  File "/opt/airflow/dags/simulative_example_basic_dag.py", line 25, in read_data_from_faker_api
    faker_api_conn = BaseHook.get_connection("faker_api")
                     ^^^^^^^^^^^^^^^^^^^^^^^^^^^^^^^^^^^^
  File "/home/airflow/.local/lib/python3.12/site-packages/airflow/hooks/base.py", line 83, in get_connection
    conn = Connection.get_connection_from_secrets(conn_id)
           ^^^^^^^^^^^^^^^^^^^^^^^^^^^^^^^^^^^^^^^^^^^^^^^
  File "/home/airflow/.local/lib/python3.12/site-packages/airflow/models/connection.py", line 537, in get_connection_from_secrets
    raise AirflowNotFoundException(f"The conn_id `{conn_id}` isn't defined")
airflow.exceptions.AirflowNotFoundException: The conn_id `faker_api` isn't defined
[2025-01-26T18:42:27.648+0000] {local_task_job_runner.py:266} INFO - Task exited with return code 1
[2025-01-26T18:42:27.697+0000] {taskinstance.py:3895} INFO - 0 downstream tasks scheduled from follow-on schedule check
[2025-01-26T18:42:27.698+0000] {local_task_job_runner.py:245} INFO - ::endgroup::
[2025-01-26T18:46:38.071+0000] {local_task_job_runner.py:123} INFO - ::group::Pre task execution logs
[2025-01-26T18:46:38.083+0000] {taskinstance.py:2613} INFO - Dependencies all met for dep_context=non-requeueable deps ti=<TaskInstance: simulative_example_basic_dag.read_data_from_faker_api_and_load_to_pg.read_data_from_faker_api scheduled__2025-01-25T00:00:00+00:00 [queued]>
[2025-01-26T18:46:38.089+0000] {taskinstance.py:2613} INFO - Dependencies all met for dep_context=requeueable deps ti=<TaskInstance: simulative_example_basic_dag.read_data_from_faker_api_and_load_to_pg.read_data_from_faker_api scheduled__2025-01-25T00:00:00+00:00 [queued]>
[2025-01-26T18:46:38.089+0000] {taskinstance.py:2866} INFO - Starting attempt 1 of 1
[2025-01-26T18:46:38.099+0000] {taskinstance.py:2889} INFO - Executing <Task(_PythonDecoratedOperator): read_data_from_faker_api_and_load_to_pg.read_data_from_faker_api> on 2025-01-25 00:00:00+00:00
[2025-01-26T18:46:38.111+0000] {warnings.py:112} WARNING - /home/***/.local/lib/python3.12/site-packages/***/task/task_runner/standard_task_runner.py:70: DeprecationWarning: This process (pid=69) is multi-threaded, use of fork() may lead to deadlocks in the child.
  pid = os.fork()

[2025-01-26T18:46:38.117+0000] {standard_task_runner.py:104} INFO - Running: ['***', 'tasks', 'run', 'simulative_example_basic_dag', 'read_data_from_faker_api_and_load_to_pg.read_data_from_faker_api', 'scheduled__2025-01-25T00:00:00+00:00', '--job-id', '6', '--raw', '--subdir', 'DAGS_FOLDER/simulative_example_basic_dag.py', '--cfg-path', '/tmp/tmp0j4wuj2y']
[2025-01-26T18:46:38.122+0000] {standard_task_runner.py:105} INFO - Job 6: Subtask read_data_from_faker_api_and_load_to_pg.read_data_from_faker_api
[2025-01-26T18:46:38.121+0000] {standard_task_runner.py:72} INFO - Started process 80 to run task
[2025-01-26T18:46:38.267+0000] {task_command.py:467} INFO - Running <TaskInstance: simulative_example_basic_dag.read_data_from_faker_api_and_load_to_pg.read_data_from_faker_api scheduled__2025-01-25T00:00:00+00:00 [running]> on host f0b50da05317
[2025-01-26T18:46:39.462+0000] {taskinstance.py:3132} INFO - Exporting env vars: AIRFLOW_CTX_DAG_OWNER='***' AIRFLOW_CTX_DAG_ID='simulative_example_basic_dag' AIRFLOW_CTX_TASK_ID='read_data_from_faker_api_and_load_to_pg.read_data_from_faker_api' AIRFLOW_CTX_EXECUTION_DATE='2025-01-25T00:00:00+00:00' AIRFLOW_CTX_TRY_NUMBER='1' AIRFLOW_CTX_DAG_RUN_ID='scheduled__2025-01-25T00:00:00+00:00'
[2025-01-26T18:46:39.463+0000] {logging_mixin.py:190} INFO - Task instance is in running state
[2025-01-26T18:46:39.463+0000] {logging_mixin.py:190} INFO -  Previous state of the Task instance: queued
[2025-01-26T18:46:39.464+0000] {logging_mixin.py:190} INFO - Current task name:read_data_from_faker_api_and_load_to_pg.read_data_from_faker_api state:running start_date:2025-01-26 18:46:38.084126+00:00
[2025-01-26T18:46:39.464+0000] {logging_mixin.py:190} INFO - Dag name:simulative_example_basic_dag and current dag run status:running
[2025-01-26T18:46:39.464+0000] {taskinstance.py:731} INFO - ::endgroup::
[2025-01-26T18:46:39.485+0000] {taskinstance.py:3311} ERROR - Task failed with exception
Traceback (most recent call last):
  File "/home/airflow/.local/lib/python3.12/site-packages/airflow/models/taskinstance.py", line 767, in _execute_task
    result = _execute_callable(context=context, **execute_callable_kwargs)
             ^^^^^^^^^^^^^^^^^^^^^^^^^^^^^^^^^^^^^^^^^^^^^^^^^^^^^^^^^^^^^
  File "/home/airflow/.local/lib/python3.12/site-packages/airflow/models/taskinstance.py", line 733, in _execute_callable
    return ExecutionCallableRunner(
           ^^^^^^^^^^^^^^^^^^^^^^^^
  File "/home/airflow/.local/lib/python3.12/site-packages/airflow/utils/operator_helpers.py", line 252, in run
    return self.func(*args, **kwargs)
           ^^^^^^^^^^^^^^^^^^^^^^^^^^
  File "/home/airflow/.local/lib/python3.12/site-packages/airflow/models/baseoperator.py", line 422, in wrapper
    return func(self, *args, **kwargs)
           ^^^^^^^^^^^^^^^^^^^^^^^^^^^
  File "/home/airflow/.local/lib/python3.12/site-packages/airflow/decorators/base.py", line 266, in execute
    return_value = super().execute(context)
                   ^^^^^^^^^^^^^^^^^^^^^^^^
  File "/home/airflow/.local/lib/python3.12/site-packages/airflow/models/baseoperator.py", line 422, in wrapper
    return func(self, *args, **kwargs)
           ^^^^^^^^^^^^^^^^^^^^^^^^^^^
  File "/home/airflow/.local/lib/python3.12/site-packages/airflow/operators/python.py", line 238, in execute
    return_value = self.execute_callable()
                   ^^^^^^^^^^^^^^^^^^^^^^^
  File "/home/airflow/.local/lib/python3.12/site-packages/airflow/operators/python.py", line 256, in execute_callable
    return runner.run(*self.op_args, **self.op_kwargs)
           ^^^^^^^^^^^^^^^^^^^^^^^^^^^^^^^^^^^^^^^^^^^
  File "/home/airflow/.local/lib/python3.12/site-packages/airflow/utils/operator_helpers.py", line 252, in run
    return self.func(*args, **kwargs)
           ^^^^^^^^^^^^^^^^^^^^^^^^^^
  File "/opt/airflow/dags/simulative_example_basic_dag.py", line 25, in read_data_from_faker_api
    faker_api_conn = BaseHook.get_connection("faker")
                     ^^^^^^^^^^^^^^^^^^^^^^^^^^^^^^^^
  File "/home/airflow/.local/lib/python3.12/site-packages/airflow/hooks/base.py", line 83, in get_connection
    conn = Connection.get_connection_from_secrets(conn_id)
           ^^^^^^^^^^^^^^^^^^^^^^^^^^^^^^^^^^^^^^^^^^^^^^^
  File "/home/airflow/.local/lib/python3.12/site-packages/airflow/models/connection.py", line 537, in get_connection_from_secrets
    raise AirflowNotFoundException(f"The conn_id `{conn_id}` isn't defined")
airflow.exceptions.AirflowNotFoundException: The conn_id `faker` isn't defined
[2025-01-26T18:46:39.506+0000] {logging_mixin.py:190} INFO - Task instance in failure state
[2025-01-26T18:46:39.507+0000] {logging_mixin.py:190} INFO - Task start:2025-01-26 18:46:38.084126+00:00 end:2025-01-26 18:46:39.505853+00:00 duration:1.421727
[2025-01-26T18:46:39.507+0000] {logging_mixin.py:190} INFO - Task:<Task(_PythonDecoratedOperator): read_data_from_faker_api_and_load_to_pg.read_data_from_faker_api> dag:<DAG: simulative_example_basic_dag> dagrun:<DagRun simulative_example_basic_dag @ 2025-01-25 00:00:00+00:00: scheduled__2025-01-25T00:00:00+00:00, state:running, queued_at: 2025-01-26 18:46:33.970706+00:00. externally triggered: False>
[2025-01-26T18:46:39.508+0000] {logging_mixin.py:190} INFO - Failure caused by The conn_id `faker` isn't defined
[2025-01-26T18:46:39.508+0000] {taskinstance.py:1225} INFO - Marking task as FAILED. dag_id=simulative_example_basic_dag, task_id=read_data_from_faker_api_and_load_to_pg.read_data_from_faker_api, run_id=scheduled__2025-01-25T00:00:00+00:00, execution_date=20250125T000000, start_date=20250126T184638, end_date=20250126T184639
[2025-01-26T18:46:39.525+0000] {taskinstance.py:340} INFO - ::group::Post task execution logs
[2025-01-26T18:46:39.527+0000] {standard_task_runner.py:124} ERROR - Failed to execute job 6 for task read_data_from_faker_api_and_load_to_pg.read_data_from_faker_api (The conn_id `faker` isn't defined; 80)
Traceback (most recent call last):
  File "/home/airflow/.local/lib/python3.12/site-packages/airflow/task/task_runner/standard_task_runner.py", line 117, in _start_by_fork
    ret = args.func(args, dag=self.dag)
          ^^^^^^^^^^^^^^^^^^^^^^^^^^^^^
  File "/home/airflow/.local/lib/python3.12/site-packages/airflow/cli/cli_config.py", line 49, in command
    return func(*args, **kwargs)
           ^^^^^^^^^^^^^^^^^^^^^
  File "/home/airflow/.local/lib/python3.12/site-packages/airflow/utils/cli.py", line 116, in wrapper
    return f(*args, **kwargs)
           ^^^^^^^^^^^^^^^^^^
  File "/home/airflow/.local/lib/python3.12/site-packages/airflow/cli/commands/task_command.py", line 483, in task_run
    task_return_code = _run_task_by_selected_method(args, _dag, ti)
                       ^^^^^^^^^^^^^^^^^^^^^^^^^^^^^^^^^^^^^^^^^^^^
  File "/home/airflow/.local/lib/python3.12/site-packages/airflow/cli/commands/task_command.py", line 256, in _run_task_by_selected_method
    return _run_raw_task(args, ti)
           ^^^^^^^^^^^^^^^^^^^^^^^
  File "/home/airflow/.local/lib/python3.12/site-packages/airflow/cli/commands/task_command.py", line 341, in _run_raw_task
    return ti._run_raw_task(
           ^^^^^^^^^^^^^^^^^
  File "/home/airflow/.local/lib/python3.12/site-packages/airflow/utils/session.py", line 97, in wrapper
    return func(*args, session=session, **kwargs)
           ^^^^^^^^^^^^^^^^^^^^^^^^^^^^^^^^^^^^^^
  File "/home/airflow/.local/lib/python3.12/site-packages/airflow/models/taskinstance.py", line 3005, in _run_raw_task
    return _run_raw_task(
           ^^^^^^^^^^^^^^
  File "/home/airflow/.local/lib/python3.12/site-packages/airflow/models/taskinstance.py", line 273, in _run_raw_task
    TaskInstance._execute_task_with_callbacks(
  File "/home/airflow/.local/lib/python3.12/site-packages/airflow/models/taskinstance.py", line 3159, in _execute_task_with_callbacks
    result = self._execute_task(context, task_orig)
             ^^^^^^^^^^^^^^^^^^^^^^^^^^^^^^^^^^^^^^
  File "/home/airflow/.local/lib/python3.12/site-packages/airflow/models/taskinstance.py", line 3183, in _execute_task
    return _execute_task(self, context, task_orig)
           ^^^^^^^^^^^^^^^^^^^^^^^^^^^^^^^^^^^^^^^
  File "/home/airflow/.local/lib/python3.12/site-packages/airflow/models/taskinstance.py", line 767, in _execute_task
    result = _execute_callable(context=context, **execute_callable_kwargs)
             ^^^^^^^^^^^^^^^^^^^^^^^^^^^^^^^^^^^^^^^^^^^^^^^^^^^^^^^^^^^^^
  File "/home/airflow/.local/lib/python3.12/site-packages/airflow/models/taskinstance.py", line 733, in _execute_callable
    return ExecutionCallableRunner(
           ^^^^^^^^^^^^^^^^^^^^^^^^
  File "/home/airflow/.local/lib/python3.12/site-packages/airflow/utils/operator_helpers.py", line 252, in run
    return self.func(*args, **kwargs)
           ^^^^^^^^^^^^^^^^^^^^^^^^^^
  File "/home/airflow/.local/lib/python3.12/site-packages/airflow/models/baseoperator.py", line 422, in wrapper
    return func(self, *args, **kwargs)
           ^^^^^^^^^^^^^^^^^^^^^^^^^^^
  File "/home/airflow/.local/lib/python3.12/site-packages/airflow/decorators/base.py", line 266, in execute
    return_value = super().execute(context)
                   ^^^^^^^^^^^^^^^^^^^^^^^^
  File "/home/airflow/.local/lib/python3.12/site-packages/airflow/models/baseoperator.py", line 422, in wrapper
    return func(self, *args, **kwargs)
           ^^^^^^^^^^^^^^^^^^^^^^^^^^^
  File "/home/airflow/.local/lib/python3.12/site-packages/airflow/operators/python.py", line 238, in execute
    return_value = self.execute_callable()
                   ^^^^^^^^^^^^^^^^^^^^^^^
  File "/home/airflow/.local/lib/python3.12/site-packages/airflow/operators/python.py", line 256, in execute_callable
    return runner.run(*self.op_args, **self.op_kwargs)
           ^^^^^^^^^^^^^^^^^^^^^^^^^^^^^^^^^^^^^^^^^^^
  File "/home/airflow/.local/lib/python3.12/site-packages/airflow/utils/operator_helpers.py", line 252, in run
    return self.func(*args, **kwargs)
           ^^^^^^^^^^^^^^^^^^^^^^^^^^
  File "/opt/airflow/dags/simulative_example_basic_dag.py", line 25, in read_data_from_faker_api
    faker_api_conn = BaseHook.get_connection("faker")
                     ^^^^^^^^^^^^^^^^^^^^^^^^^^^^^^^^
  File "/home/airflow/.local/lib/python3.12/site-packages/airflow/hooks/base.py", line 83, in get_connection
    conn = Connection.get_connection_from_secrets(conn_id)
           ^^^^^^^^^^^^^^^^^^^^^^^^^^^^^^^^^^^^^^^^^^^^^^^
  File "/home/airflow/.local/lib/python3.12/site-packages/airflow/models/connection.py", line 537, in get_connection_from_secrets
    raise AirflowNotFoundException(f"The conn_id `{conn_id}` isn't defined")
airflow.exceptions.AirflowNotFoundException: The conn_id `faker` isn't defined
[2025-01-26T18:46:39.562+0000] {local_task_job_runner.py:266} INFO - Task exited with return code 1
[2025-01-26T18:46:39.594+0000] {local_task_job_runner.py:245} INFO - ::endgroup::
[2025-01-26T18:52:12.665+0000] {local_task_job_runner.py:123} INFO - ::group::Pre task execution logs
[2025-01-26T18:52:12.673+0000] {taskinstance.py:2613} INFO - Dependencies all met for dep_context=non-requeueable deps ti=<TaskInstance: simulative_example_basic_dag.read_data_from_faker_api_and_load_to_pg.read_data_from_faker_api scheduled__2025-01-25T00:00:00+00:00 [queued]>
[2025-01-26T18:52:12.678+0000] {taskinstance.py:2613} INFO - Dependencies all met for dep_context=requeueable deps ti=<TaskInstance: simulative_example_basic_dag.read_data_from_faker_api_and_load_to_pg.read_data_from_faker_api scheduled__2025-01-25T00:00:00+00:00 [queued]>
[2025-01-26T18:52:12.678+0000] {taskinstance.py:2866} INFO - Starting attempt 1 of 1
[2025-01-26T18:52:12.686+0000] {taskinstance.py:2889} INFO - Executing <Task(_PythonDecoratedOperator): read_data_from_faker_api_and_load_to_pg.read_data_from_faker_api> on 2025-01-25 00:00:00+00:00
[2025-01-26T18:52:12.692+0000] {warnings.py:112} WARNING - /home/***/.local/lib/python3.12/site-packages/***/task/task_runner/standard_task_runner.py:70: DeprecationWarning: This process (pid=71) is multi-threaded, use of fork() may lead to deadlocks in the child.
  pid = os.fork()

[2025-01-26T18:52:12.694+0000] {standard_task_runner.py:72} INFO - Started process 78 to run task
[2025-01-26T18:52:12.697+0000] {standard_task_runner.py:104} INFO - Running: ['***', 'tasks', 'run', 'simulative_example_basic_dag', 'read_data_from_faker_api_and_load_to_pg.read_data_from_faker_api', 'scheduled__2025-01-25T00:00:00+00:00', '--job-id', '4', '--raw', '--subdir', 'DAGS_FOLDER/simulative_example_basic_dag.py', '--cfg-path', '/tmp/tmphu7z4p9z']
[2025-01-26T18:52:12.698+0000] {standard_task_runner.py:105} INFO - Job 4: Subtask read_data_from_faker_api_and_load_to_pg.read_data_from_faker_api
[2025-01-26T18:52:13.095+0000] {task_command.py:467} INFO - Running <TaskInstance: simulative_example_basic_dag.read_data_from_faker_api_and_load_to_pg.read_data_from_faker_api scheduled__2025-01-25T00:00:00+00:00 [running]> on host 7f022d612633
[2025-01-26T18:52:13.178+0000] {taskinstance.py:3132} INFO - Exporting env vars: AIRFLOW_CTX_DAG_OWNER='***' AIRFLOW_CTX_DAG_ID='simulative_example_basic_dag' AIRFLOW_CTX_TASK_ID='read_data_from_faker_api_and_load_to_pg.read_data_from_faker_api' AIRFLOW_CTX_EXECUTION_DATE='2025-01-25T00:00:00+00:00' AIRFLOW_CTX_TRY_NUMBER='1' AIRFLOW_CTX_DAG_RUN_ID='scheduled__2025-01-25T00:00:00+00:00'
[2025-01-26T18:52:13.181+0000] {logging_mixin.py:190} INFO - Task instance is in running state
[2025-01-26T18:52:13.182+0000] {logging_mixin.py:190} INFO -  Previous state of the Task instance: queued
[2025-01-26T18:52:13.182+0000] {logging_mixin.py:190} INFO - Current task name:read_data_from_faker_api_and_load_to_pg.read_data_from_faker_api state:running start_date:2025-01-26 18:52:12.674521+00:00
[2025-01-26T18:52:13.183+0000] {logging_mixin.py:190} INFO - Dag name:simulative_example_basic_dag and current dag run status:running
[2025-01-26T18:52:13.183+0000] {taskinstance.py:731} INFO - ::endgroup::
[2025-01-26T18:52:13.184+0000] {connection.py:531} ERROR - Unable to retrieve connection from secrets backend (LocalFilesystemBackend). Checking subsequent secrets backend.
Traceback (most recent call last):
  File "/home/airflow/.local/lib/python3.12/site-packages/airflow/models/connection.py", line 526, in get_connection_from_secrets
    conn = secrets_backend.get_connection(conn_id=conn_id)
           ^^^^^^^^^^^^^^^^^^^^^^^^^^^^^^^^^^^^^^^^^^^^^^^
  File "/home/airflow/.local/lib/python3.12/site-packages/airflow/secrets/local_filesystem.py", line 317, in get_connection
    if conn_id in self._local_connections:
                  ^^^^^^^^^^^^^^^^^^^^^^^
  File "/home/airflow/.local/lib/python3.12/site-packages/airflow/secrets/local_filesystem.py", line 314, in _local_connections
    return load_connections_dict(self.connections_file)
           ^^^^^^^^^^^^^^^^^^^^^^^^^^^^^^^^^^^^^^^^^^^^
  File "/home/airflow/.local/lib/python3.12/site-packages/airflow/secrets/local_filesystem.py", line 266, in load_connections_dict
    secrets: dict[str, Any] = _parse_secret_file(file_path)
                              ^^^^^^^^^^^^^^^^^^^^^^^^^^^^^
  File "/home/airflow/.local/lib/python3.12/site-packages/airflow/secrets/local_filesystem.py", line 163, in _parse_secret_file
    raise AirflowException(
airflow.exceptions.AirflowException: File /opt/***/data/connections.yml was not found. Check the configuration of your Secrets backend.
[2025-01-26T18:52:13.198+0000] {taskinstance.py:3311} ERROR - Task failed with exception
Traceback (most recent call last):
  File "/home/airflow/.local/lib/python3.12/site-packages/airflow/models/taskinstance.py", line 767, in _execute_task
    result = _execute_callable(context=context, **execute_callable_kwargs)
             ^^^^^^^^^^^^^^^^^^^^^^^^^^^^^^^^^^^^^^^^^^^^^^^^^^^^^^^^^^^^^
  File "/home/airflow/.local/lib/python3.12/site-packages/airflow/models/taskinstance.py", line 733, in _execute_callable
    return ExecutionCallableRunner(
           ^^^^^^^^^^^^^^^^^^^^^^^^
  File "/home/airflow/.local/lib/python3.12/site-packages/airflow/utils/operator_helpers.py", line 252, in run
    return self.func(*args, **kwargs)
           ^^^^^^^^^^^^^^^^^^^^^^^^^^
  File "/home/airflow/.local/lib/python3.12/site-packages/airflow/models/baseoperator.py", line 422, in wrapper
    return func(self, *args, **kwargs)
           ^^^^^^^^^^^^^^^^^^^^^^^^^^^
  File "/home/airflow/.local/lib/python3.12/site-packages/airflow/decorators/base.py", line 266, in execute
    return_value = super().execute(context)
                   ^^^^^^^^^^^^^^^^^^^^^^^^
  File "/home/airflow/.local/lib/python3.12/site-packages/airflow/models/baseoperator.py", line 422, in wrapper
    return func(self, *args, **kwargs)
           ^^^^^^^^^^^^^^^^^^^^^^^^^^^
  File "/home/airflow/.local/lib/python3.12/site-packages/airflow/operators/python.py", line 238, in execute
    return_value = self.execute_callable()
                   ^^^^^^^^^^^^^^^^^^^^^^^
  File "/home/airflow/.local/lib/python3.12/site-packages/airflow/operators/python.py", line 256, in execute_callable
    return runner.run(*self.op_args, **self.op_kwargs)
           ^^^^^^^^^^^^^^^^^^^^^^^^^^^^^^^^^^^^^^^^^^^
  File "/home/airflow/.local/lib/python3.12/site-packages/airflow/utils/operator_helpers.py", line 252, in run
    return self.func(*args, **kwargs)
           ^^^^^^^^^^^^^^^^^^^^^^^^^^
  File "/opt/airflow/dags/simulative_example_basic_dag.py", line 25, in read_data_from_faker_api
    faker_api_conn = BaseHook.get_connection("faker")
                     ^^^^^^^^^^^^^^^^^^^^^^^^^^^^^^^^
  File "/home/airflow/.local/lib/python3.12/site-packages/airflow/hooks/base.py", line 83, in get_connection
    conn = Connection.get_connection_from_secrets(conn_id)
           ^^^^^^^^^^^^^^^^^^^^^^^^^^^^^^^^^^^^^^^^^^^^^^^
  File "/home/airflow/.local/lib/python3.12/site-packages/airflow/models/connection.py", line 537, in get_connection_from_secrets
    raise AirflowNotFoundException(f"The conn_id `{conn_id}` isn't defined")
airflow.exceptions.AirflowNotFoundException: The conn_id `faker` isn't defined
[2025-01-26T18:52:13.204+0000] {logging_mixin.py:190} INFO - Task instance in failure state
[2025-01-26T18:52:13.205+0000] {logging_mixin.py:190} INFO - Task start:2025-01-26 18:52:12.674521+00:00 end:2025-01-26 18:52:13.203168+00:00 duration:0.528647
[2025-01-26T18:52:13.205+0000] {logging_mixin.py:190} INFO - Task:<Task(_PythonDecoratedOperator): read_data_from_faker_api_and_load_to_pg.read_data_from_faker_api> dag:<DAG: simulative_example_basic_dag> dagrun:<DagRun simulative_example_basic_dag @ 2025-01-25 00:00:00+00:00: scheduled__2025-01-25T00:00:00+00:00, state:running, queued_at: 2025-01-26 18:52:09.254469+00:00. externally triggered: False>
[2025-01-26T18:52:13.206+0000] {logging_mixin.py:190} INFO - Failure caused by The conn_id `faker` isn't defined
[2025-01-26T18:52:13.207+0000] {taskinstance.py:1225} INFO - Marking task as FAILED. dag_id=simulative_example_basic_dag, task_id=read_data_from_faker_api_and_load_to_pg.read_data_from_faker_api, run_id=scheduled__2025-01-25T00:00:00+00:00, execution_date=20250125T000000, start_date=20250126T185212, end_date=20250126T185213
[2025-01-26T18:52:13.218+0000] {taskinstance.py:340} INFO - ::group::Post task execution logs
[2025-01-26T18:52:13.218+0000] {standard_task_runner.py:124} ERROR - Failed to execute job 4 for task read_data_from_faker_api_and_load_to_pg.read_data_from_faker_api (The conn_id `faker` isn't defined; 78)
Traceback (most recent call last):
  File "/home/airflow/.local/lib/python3.12/site-packages/airflow/task/task_runner/standard_task_runner.py", line 117, in _start_by_fork
    ret = args.func(args, dag=self.dag)
          ^^^^^^^^^^^^^^^^^^^^^^^^^^^^^
  File "/home/airflow/.local/lib/python3.12/site-packages/airflow/cli/cli_config.py", line 49, in command
    return func(*args, **kwargs)
           ^^^^^^^^^^^^^^^^^^^^^
  File "/home/airflow/.local/lib/python3.12/site-packages/airflow/utils/cli.py", line 116, in wrapper
    return f(*args, **kwargs)
           ^^^^^^^^^^^^^^^^^^
  File "/home/airflow/.local/lib/python3.12/site-packages/airflow/cli/commands/task_command.py", line 483, in task_run
    task_return_code = _run_task_by_selected_method(args, _dag, ti)
                       ^^^^^^^^^^^^^^^^^^^^^^^^^^^^^^^^^^^^^^^^^^^^
  File "/home/airflow/.local/lib/python3.12/site-packages/airflow/cli/commands/task_command.py", line 256, in _run_task_by_selected_method
    return _run_raw_task(args, ti)
           ^^^^^^^^^^^^^^^^^^^^^^^
  File "/home/airflow/.local/lib/python3.12/site-packages/airflow/cli/commands/task_command.py", line 341, in _run_raw_task
    return ti._run_raw_task(
           ^^^^^^^^^^^^^^^^^
  File "/home/airflow/.local/lib/python3.12/site-packages/airflow/utils/session.py", line 97, in wrapper
    return func(*args, session=session, **kwargs)
           ^^^^^^^^^^^^^^^^^^^^^^^^^^^^^^^^^^^^^^
  File "/home/airflow/.local/lib/python3.12/site-packages/airflow/models/taskinstance.py", line 3005, in _run_raw_task
    return _run_raw_task(
           ^^^^^^^^^^^^^^
  File "/home/airflow/.local/lib/python3.12/site-packages/airflow/models/taskinstance.py", line 273, in _run_raw_task
    TaskInstance._execute_task_with_callbacks(
  File "/home/airflow/.local/lib/python3.12/site-packages/airflow/models/taskinstance.py", line 3159, in _execute_task_with_callbacks
    result = self._execute_task(context, task_orig)
             ^^^^^^^^^^^^^^^^^^^^^^^^^^^^^^^^^^^^^^
  File "/home/airflow/.local/lib/python3.12/site-packages/airflow/models/taskinstance.py", line 3183, in _execute_task
    return _execute_task(self, context, task_orig)
           ^^^^^^^^^^^^^^^^^^^^^^^^^^^^^^^^^^^^^^^
  File "/home/airflow/.local/lib/python3.12/site-packages/airflow/models/taskinstance.py", line 767, in _execute_task
    result = _execute_callable(context=context, **execute_callable_kwargs)
             ^^^^^^^^^^^^^^^^^^^^^^^^^^^^^^^^^^^^^^^^^^^^^^^^^^^^^^^^^^^^^
  File "/home/airflow/.local/lib/python3.12/site-packages/airflow/models/taskinstance.py", line 733, in _execute_callable
    return ExecutionCallableRunner(
           ^^^^^^^^^^^^^^^^^^^^^^^^
  File "/home/airflow/.local/lib/python3.12/site-packages/airflow/utils/operator_helpers.py", line 252, in run
    return self.func(*args, **kwargs)
           ^^^^^^^^^^^^^^^^^^^^^^^^^^
  File "/home/airflow/.local/lib/python3.12/site-packages/airflow/models/baseoperator.py", line 422, in wrapper
    return func(self, *args, **kwargs)
           ^^^^^^^^^^^^^^^^^^^^^^^^^^^
  File "/home/airflow/.local/lib/python3.12/site-packages/airflow/decorators/base.py", line 266, in execute
    return_value = super().execute(context)
                   ^^^^^^^^^^^^^^^^^^^^^^^^
  File "/home/airflow/.local/lib/python3.12/site-packages/airflow/models/baseoperator.py", line 422, in wrapper
    return func(self, *args, **kwargs)
           ^^^^^^^^^^^^^^^^^^^^^^^^^^^
  File "/home/airflow/.local/lib/python3.12/site-packages/airflow/operators/python.py", line 238, in execute
    return_value = self.execute_callable()
                   ^^^^^^^^^^^^^^^^^^^^^^^
  File "/home/airflow/.local/lib/python3.12/site-packages/airflow/operators/python.py", line 256, in execute_callable
    return runner.run(*self.op_args, **self.op_kwargs)
           ^^^^^^^^^^^^^^^^^^^^^^^^^^^^^^^^^^^^^^^^^^^
  File "/home/airflow/.local/lib/python3.12/site-packages/airflow/utils/operator_helpers.py", line 252, in run
    return self.func(*args, **kwargs)
           ^^^^^^^^^^^^^^^^^^^^^^^^^^
  File "/opt/airflow/dags/simulative_example_basic_dag.py", line 25, in read_data_from_faker_api
    faker_api_conn = BaseHook.get_connection("faker")
                     ^^^^^^^^^^^^^^^^^^^^^^^^^^^^^^^^
  File "/home/airflow/.local/lib/python3.12/site-packages/airflow/hooks/base.py", line 83, in get_connection
    conn = Connection.get_connection_from_secrets(conn_id)
           ^^^^^^^^^^^^^^^^^^^^^^^^^^^^^^^^^^^^^^^^^^^^^^^
  File "/home/airflow/.local/lib/python3.12/site-packages/airflow/models/connection.py", line 537, in get_connection_from_secrets
    raise AirflowNotFoundException(f"The conn_id `{conn_id}` isn't defined")
airflow.exceptions.AirflowNotFoundException: The conn_id `faker` isn't defined
[2025-01-26T18:52:13.244+0000] {local_task_job_runner.py:266} INFO - Task exited with return code 1
[2025-01-26T18:52:13.263+0000] {local_task_job_runner.py:245} INFO - ::endgroup::
[2025-01-26T18:53:58.823+0000] {local_task_job_runner.py:123} INFO - ::group::Pre task execution logs
[2025-01-26T18:53:58.834+0000] {taskinstance.py:2613} INFO - Dependencies all met for dep_context=non-requeueable deps ti=<TaskInstance: simulative_example_basic_dag.read_data_from_faker_api_and_load_to_pg.read_data_from_faker_api scheduled__2025-01-25T00:00:00+00:00 [queued]>
[2025-01-26T18:53:58.841+0000] {taskinstance.py:2613} INFO - Dependencies all met for dep_context=requeueable deps ti=<TaskInstance: simulative_example_basic_dag.read_data_from_faker_api_and_load_to_pg.read_data_from_faker_api scheduled__2025-01-25T00:00:00+00:00 [queued]>
[2025-01-26T18:53:58.842+0000] {taskinstance.py:2866} INFO - Starting attempt 1 of 1
[2025-01-26T18:53:58.854+0000] {taskinstance.py:2889} INFO - Executing <Task(_PythonDecoratedOperator): read_data_from_faker_api_and_load_to_pg.read_data_from_faker_api> on 2025-01-25 00:00:00+00:00
[2025-01-26T18:53:58.858+0000] {warnings.py:112} WARNING - /home/***/.local/lib/python3.12/site-packages/***/task/task_runner/standard_task_runner.py:70: DeprecationWarning: This process (pid=71) is multi-threaded, use of fork() may lead to deadlocks in the child.
  pid = os.fork()

[2025-01-26T18:53:58.859+0000] {standard_task_runner.py:72} INFO - Started process 79 to run task
[2025-01-26T18:53:58.862+0000] {standard_task_runner.py:104} INFO - Running: ['***', 'tasks', 'run', 'simulative_example_basic_dag', 'read_data_from_faker_api_and_load_to_pg.read_data_from_faker_api', 'scheduled__2025-01-25T00:00:00+00:00', '--job-id', '4', '--raw', '--subdir', 'DAGS_FOLDER/simulative_example_basic_dag.py', '--cfg-path', '/tmp/tmpgawyqvje']
[2025-01-26T18:53:58.863+0000] {standard_task_runner.py:105} INFO - Job 4: Subtask read_data_from_faker_api_and_load_to_pg.read_data_from_faker_api
[2025-01-26T18:53:59.362+0000] {task_command.py:467} INFO - Running <TaskInstance: simulative_example_basic_dag.read_data_from_faker_api_and_load_to_pg.read_data_from_faker_api scheduled__2025-01-25T00:00:00+00:00 [running]> on host b82bd748d7ce
[2025-01-26T18:53:59.406+0000] {taskinstance.py:3132} INFO - Exporting env vars: AIRFLOW_CTX_DAG_OWNER='***' AIRFLOW_CTX_DAG_ID='simulative_example_basic_dag' AIRFLOW_CTX_TASK_ID='read_data_from_faker_api_and_load_to_pg.read_data_from_faker_api' AIRFLOW_CTX_EXECUTION_DATE='2025-01-25T00:00:00+00:00' AIRFLOW_CTX_TRY_NUMBER='1' AIRFLOW_CTX_DAG_RUN_ID='scheduled__2025-01-25T00:00:00+00:00'
[2025-01-26T18:53:59.407+0000] {logging_mixin.py:190} INFO - Task instance is in running state
[2025-01-26T18:53:59.407+0000] {logging_mixin.py:190} INFO -  Previous state of the Task instance: queued
[2025-01-26T18:53:59.407+0000] {logging_mixin.py:190} INFO - Current task name:read_data_from_faker_api_and_load_to_pg.read_data_from_faker_api state:running start_date:2025-01-26 18:53:58.835400+00:00
[2025-01-26T18:53:59.407+0000] {logging_mixin.py:190} INFO - Dag name:simulative_example_basic_dag and current dag run status:running
[2025-01-26T18:53:59.407+0000] {taskinstance.py:731} INFO - ::endgroup::
[2025-01-26T18:53:59.409+0000] {crypto.py:82} WARNING - empty cryptography key - values will not be stored encrypted.
[2025-01-26T18:53:59.410+0000] {base.py:84} INFO - Retrieving connection 'faker'
[2025-01-26T18:53:59.501+0000] {python.py:240} INFO - Done. Returned value was: None
[2025-01-26T18:53:59.511+0000] {taskinstance.py:340} INFO - ::group::Post task execution logs
[2025-01-26T18:53:59.512+0000] {taskinstance.py:352} INFO - Marking task as SUCCESS. dag_id=simulative_example_basic_dag, task_id=read_data_from_faker_api_and_load_to_pg.read_data_from_faker_api, run_id=scheduled__2025-01-25T00:00:00+00:00, execution_date=20250125T000000, start_date=20250126T185358, end_date=20250126T185359
[2025-01-26T18:53:59.521+0000] {logging_mixin.py:190} INFO - Task instance in success state
[2025-01-26T18:53:59.522+0000] {logging_mixin.py:190} INFO -  Previous state of the Task instance: running
[2025-01-26T18:53:59.523+0000] {logging_mixin.py:190} INFO - Dag name:simulative_example_basic_dag queued_at:2025-01-26 18:53:55.413788+00:00
[2025-01-26T18:53:59.524+0000] {logging_mixin.py:190} INFO - Task hostname:b82bd748d7ce operator:_PythonDecoratedOperator
[2025-01-26T18:53:59.534+0000] {local_task_job_runner.py:266} INFO - Task exited with return code 0
[2025-01-26T18:53:59.542+0000] {local_task_job_runner.py:245} INFO - ::endgroup::
