[2025-01-26T18:42:25.868+0000] {local_task_job_runner.py:123} INFO - ::group::Pre task execution logs
[2025-01-26T18:42:26.005+0000] {taskinstance.py:2613} INFO - Dependencies all met for dep_context=non-requeueable deps ti=<TaskInstance: simulative_example_basic_dag.read_data_from_faker_api_and_load_to_pg.load_data_to_pg scheduled__2025-01-25T00:00:00+00:00 [queued]>
[2025-01-26T18:42:26.069+0000] {taskinstance.py:2613} INFO - Dependencies all met for dep_context=requeueable deps ti=<TaskInstance: simulative_example_basic_dag.read_data_from_faker_api_and_load_to_pg.load_data_to_pg scheduled__2025-01-25T00:00:00+00:00 [queued]>
[2025-01-26T18:42:26.072+0000] {taskinstance.py:2866} INFO - Starting attempt 1 of 1
[2025-01-26T18:42:26.109+0000] {taskinstance.py:2889} INFO - Executing <Task(_PythonDecoratedOperator): read_data_from_faker_api_and_load_to_pg.load_data_to_pg> on 2025-01-25 00:00:00+00:00
[2025-01-26T18:42:26.166+0000] {warnings.py:112} WARNING - /home/***/.local/lib/python3.12/site-packages/***/task/task_runner/standard_task_runner.py:70: DeprecationWarning: This process (pid=71) is multi-threaded, use of fork() may lead to deadlocks in the child.
  pid = os.fork()

[2025-01-26T18:42:26.179+0000] {standard_task_runner.py:72} INFO - Started process 94 to run task
[2025-01-26T18:42:26.206+0000] {standard_task_runner.py:104} INFO - Running: ['***', 'tasks', 'run', 'simulative_example_basic_dag', 'read_data_from_faker_api_and_load_to_pg.load_data_to_pg', 'scheduled__2025-01-25T00:00:00+00:00', '--job-id', '8', '--raw', '--subdir', 'DAGS_FOLDER/simulative_example_basic_dag.py', '--cfg-path', '/tmp/tmpvh49isyp']
[2025-01-26T18:42:26.211+0000] {standard_task_runner.py:105} INFO - Job 8: Subtask read_data_from_faker_api_and_load_to_pg.load_data_to_pg
[2025-01-26T18:42:26.569+0000] {task_command.py:467} INFO - Running <TaskInstance: simulative_example_basic_dag.read_data_from_faker_api_and_load_to_pg.load_data_to_pg scheduled__2025-01-25T00:00:00+00:00 [running]> on host 3cfc25a6c20c
[2025-01-26T18:42:26.967+0000] {taskinstance.py:3132} INFO - Exporting env vars: AIRFLOW_CTX_DAG_OWNER='***' AIRFLOW_CTX_DAG_ID='simulative_example_basic_dag' AIRFLOW_CTX_TASK_ID='read_data_from_faker_api_and_load_to_pg.load_data_to_pg' AIRFLOW_CTX_EXECUTION_DATE='2025-01-25T00:00:00+00:00' AIRFLOW_CTX_TRY_NUMBER='1' AIRFLOW_CTX_DAG_RUN_ID='scheduled__2025-01-25T00:00:00+00:00'
[2025-01-26T18:42:26.982+0000] {logging_mixin.py:190} INFO - Task instance is in running state
[2025-01-26T18:42:26.984+0000] {logging_mixin.py:190} INFO -  Previous state of the Task instance: queued
[2025-01-26T18:42:26.986+0000] {logging_mixin.py:190} INFO - Current task name:read_data_from_faker_api_and_load_to_pg.load_data_to_pg state:running start_date:2025-01-26 18:42:26.017160+00:00
[2025-01-26T18:42:26.987+0000] {logging_mixin.py:190} INFO - Dag name:simulative_example_basic_dag and current dag run status:running
[2025-01-26T18:42:26.993+0000] {taskinstance.py:731} INFO - ::endgroup::
[2025-01-26T18:42:27.031+0000] {logging_mixin.py:190} INFO - None
[2025-01-26T18:42:27.118+0000] {taskinstance.py:3311} ERROR - Task failed with exception
Traceback (most recent call last):
  File "/home/airflow/.local/lib/python3.12/site-packages/airflow/models/taskinstance.py", line 767, in _execute_task
    result = _execute_callable(context=context, **execute_callable_kwargs)
             ^^^^^^^^^^^^^^^^^^^^^^^^^^^^^^^^^^^^^^^^^^^^^^^^^^^^^^^^^^^^^
  File "/home/airflow/.local/lib/python3.12/site-packages/airflow/models/taskinstance.py", line 733, in _execute_callable
    return ExecutionCallableRunner(
           ^^^^^^^^^^^^^^^^^^^^^^^^
  File "/home/airflow/.local/lib/python3.12/site-packages/airflow/utils/operator_helpers.py", line 252, in run
    return self.func(*args, **kwargs)
           ^^^^^^^^^^^^^^^^^^^^^^^^^^
  File "/home/airflow/.local/lib/python3.12/site-packages/airflow/models/baseoperator.py", line 422, in wrapper
    return func(self, *args, **kwargs)
           ^^^^^^^^^^^^^^^^^^^^^^^^^^^
  File "/home/airflow/.local/lib/python3.12/site-packages/airflow/decorators/base.py", line 266, in execute
    return_value = super().execute(context)
                   ^^^^^^^^^^^^^^^^^^^^^^^^
  File "/home/airflow/.local/lib/python3.12/site-packages/airflow/models/baseoperator.py", line 422, in wrapper
    return func(self, *args, **kwargs)
           ^^^^^^^^^^^^^^^^^^^^^^^^^^^
  File "/home/airflow/.local/lib/python3.12/site-packages/airflow/operators/python.py", line 238, in execute
    return_value = self.execute_callable()
                   ^^^^^^^^^^^^^^^^^^^^^^^
  File "/home/airflow/.local/lib/python3.12/site-packages/airflow/operators/python.py", line 256, in execute_callable
    return runner.run(*self.op_args, **self.op_kwargs)
           ^^^^^^^^^^^^^^^^^^^^^^^^^^^^^^^^^^^^^^^^^^^
  File "/home/airflow/.local/lib/python3.12/site-packages/airflow/utils/operator_helpers.py", line 252, in run
    return self.func(*args, **kwargs)
           ^^^^^^^^^^^^^^^^^^^^^^^^^^
  File "/opt/airflow/dags/simulative_example_basic_dag.py", line 45, in load_data_to_pg
    pg_conn = BaseHook.get_connection("postgres_conn")
              ^^^^^^^^^^^^^^^^^^^^^^^^^^^^^^^^^^^^^^^^
  File "/home/airflow/.local/lib/python3.12/site-packages/airflow/hooks/base.py", line 83, in get_connection
    conn = Connection.get_connection_from_secrets(conn_id)
           ^^^^^^^^^^^^^^^^^^^^^^^^^^^^^^^^^^^^^^^^^^^^^^^
  File "/home/airflow/.local/lib/python3.12/site-packages/airflow/models/connection.py", line 537, in get_connection_from_secrets
    raise AirflowNotFoundException(f"The conn_id `{conn_id}` isn't defined")
airflow.exceptions.AirflowNotFoundException: The conn_id `postgres_conn` isn't defined
[2025-01-26T18:42:27.164+0000] {logging_mixin.py:190} INFO - Task instance in failure state
[2025-01-26T18:42:27.165+0000] {logging_mixin.py:190} INFO - Task start:2025-01-26 18:42:26.017160+00:00 end:2025-01-26 18:42:27.162641+00:00 duration:1.145481
[2025-01-26T18:42:27.165+0000] {logging_mixin.py:190} INFO - Task:<Task(_PythonDecoratedOperator): read_data_from_faker_api_and_load_to_pg.load_data_to_pg> dag:<DAG: simulative_example_basic_dag> dagrun:<DagRun simulative_example_basic_dag @ 2025-01-25 00:00:00+00:00: scheduled__2025-01-25T00:00:00+00:00, state:running, queued_at: 2025-01-26 18:42:18.367876+00:00. externally triggered: False>
[2025-01-26T18:42:27.166+0000] {logging_mixin.py:190} INFO - Failure caused by The conn_id `postgres_conn` isn't defined
[2025-01-26T18:42:27.169+0000] {taskinstance.py:1225} INFO - Marking task as FAILED. dag_id=simulative_example_basic_dag, task_id=read_data_from_faker_api_and_load_to_pg.load_data_to_pg, run_id=scheduled__2025-01-25T00:00:00+00:00, execution_date=20250125T000000, start_date=20250126T184226, end_date=20250126T184227
[2025-01-26T18:42:27.240+0000] {taskinstance.py:340} INFO - ::group::Post task execution logs
[2025-01-26T18:42:27.242+0000] {standard_task_runner.py:124} ERROR - Failed to execute job 8 for task read_data_from_faker_api_and_load_to_pg.load_data_to_pg (The conn_id `postgres_conn` isn't defined; 94)
Traceback (most recent call last):
  File "/home/airflow/.local/lib/python3.12/site-packages/airflow/task/task_runner/standard_task_runner.py", line 117, in _start_by_fork
    ret = args.func(args, dag=self.dag)
          ^^^^^^^^^^^^^^^^^^^^^^^^^^^^^
  File "/home/airflow/.local/lib/python3.12/site-packages/airflow/cli/cli_config.py", line 49, in command
    return func(*args, **kwargs)
           ^^^^^^^^^^^^^^^^^^^^^
  File "/home/airflow/.local/lib/python3.12/site-packages/airflow/utils/cli.py", line 116, in wrapper
    return f(*args, **kwargs)
           ^^^^^^^^^^^^^^^^^^
  File "/home/airflow/.local/lib/python3.12/site-packages/airflow/cli/commands/task_command.py", line 483, in task_run
    task_return_code = _run_task_by_selected_method(args, _dag, ti)
                       ^^^^^^^^^^^^^^^^^^^^^^^^^^^^^^^^^^^^^^^^^^^^
  File "/home/airflow/.local/lib/python3.12/site-packages/airflow/cli/commands/task_command.py", line 256, in _run_task_by_selected_method
    return _run_raw_task(args, ti)
           ^^^^^^^^^^^^^^^^^^^^^^^
  File "/home/airflow/.local/lib/python3.12/site-packages/airflow/cli/commands/task_command.py", line 341, in _run_raw_task
    return ti._run_raw_task(
           ^^^^^^^^^^^^^^^^^
  File "/home/airflow/.local/lib/python3.12/site-packages/airflow/utils/session.py", line 97, in wrapper
    return func(*args, session=session, **kwargs)
           ^^^^^^^^^^^^^^^^^^^^^^^^^^^^^^^^^^^^^^
  File "/home/airflow/.local/lib/python3.12/site-packages/airflow/models/taskinstance.py", line 3005, in _run_raw_task
    return _run_raw_task(
           ^^^^^^^^^^^^^^
  File "/home/airflow/.local/lib/python3.12/site-packages/airflow/models/taskinstance.py", line 273, in _run_raw_task
    TaskInstance._execute_task_with_callbacks(
  File "/home/airflow/.local/lib/python3.12/site-packages/airflow/models/taskinstance.py", line 3159, in _execute_task_with_callbacks
    result = self._execute_task(context, task_orig)
             ^^^^^^^^^^^^^^^^^^^^^^^^^^^^^^^^^^^^^^
  File "/home/airflow/.local/lib/python3.12/site-packages/airflow/models/taskinstance.py", line 3183, in _execute_task
    return _execute_task(self, context, task_orig)
           ^^^^^^^^^^^^^^^^^^^^^^^^^^^^^^^^^^^^^^^
  File "/home/airflow/.local/lib/python3.12/site-packages/airflow/models/taskinstance.py", line 767, in _execute_task
    result = _execute_callable(context=context, **execute_callable_kwargs)
             ^^^^^^^^^^^^^^^^^^^^^^^^^^^^^^^^^^^^^^^^^^^^^^^^^^^^^^^^^^^^^
  File "/home/airflow/.local/lib/python3.12/site-packages/airflow/models/taskinstance.py", line 733, in _execute_callable
    return ExecutionCallableRunner(
           ^^^^^^^^^^^^^^^^^^^^^^^^
  File "/home/airflow/.local/lib/python3.12/site-packages/airflow/utils/operator_helpers.py", line 252, in run
    return self.func(*args, **kwargs)
           ^^^^^^^^^^^^^^^^^^^^^^^^^^
  File "/home/airflow/.local/lib/python3.12/site-packages/airflow/models/baseoperator.py", line 422, in wrapper
    return func(self, *args, **kwargs)
           ^^^^^^^^^^^^^^^^^^^^^^^^^^^
  File "/home/airflow/.local/lib/python3.12/site-packages/airflow/decorators/base.py", line 266, in execute
    return_value = super().execute(context)
                   ^^^^^^^^^^^^^^^^^^^^^^^^
  File "/home/airflow/.local/lib/python3.12/site-packages/airflow/models/baseoperator.py", line 422, in wrapper
    return func(self, *args, **kwargs)
           ^^^^^^^^^^^^^^^^^^^^^^^^^^^
  File "/home/airflow/.local/lib/python3.12/site-packages/airflow/operators/python.py", line 238, in execute
    return_value = self.execute_callable()
                   ^^^^^^^^^^^^^^^^^^^^^^^
  File "/home/airflow/.local/lib/python3.12/site-packages/airflow/operators/python.py", line 256, in execute_callable
    return runner.run(*self.op_args, **self.op_kwargs)
           ^^^^^^^^^^^^^^^^^^^^^^^^^^^^^^^^^^^^^^^^^^^
  File "/home/airflow/.local/lib/python3.12/site-packages/airflow/utils/operator_helpers.py", line 252, in run
    return self.func(*args, **kwargs)
           ^^^^^^^^^^^^^^^^^^^^^^^^^^
  File "/opt/airflow/dags/simulative_example_basic_dag.py", line 45, in load_data_to_pg
    pg_conn = BaseHook.get_connection("postgres_conn")
              ^^^^^^^^^^^^^^^^^^^^^^^^^^^^^^^^^^^^^^^^
  File "/home/airflow/.local/lib/python3.12/site-packages/airflow/hooks/base.py", line 83, in get_connection
    conn = Connection.get_connection_from_secrets(conn_id)
           ^^^^^^^^^^^^^^^^^^^^^^^^^^^^^^^^^^^^^^^^^^^^^^^
  File "/home/airflow/.local/lib/python3.12/site-packages/airflow/models/connection.py", line 537, in get_connection_from_secrets
    raise AirflowNotFoundException(f"The conn_id `{conn_id}` isn't defined")
airflow.exceptions.AirflowNotFoundException: The conn_id `postgres_conn` isn't defined
[2025-01-26T18:42:27.286+0000] {local_task_job_runner.py:266} INFO - Task exited with return code 1
[2025-01-26T18:42:27.352+0000] {taskinstance.py:3895} INFO - 0 downstream tasks scheduled from follow-on schedule check
[2025-01-26T18:42:27.366+0000] {local_task_job_runner.py:245} INFO - ::endgroup::
[2025-01-26T18:46:38.341+0000] {local_task_job_runner.py:123} INFO - ::group::Pre task execution logs
[2025-01-26T18:46:38.381+0000] {taskinstance.py:2613} INFO - Dependencies all met for dep_context=non-requeueable deps ti=<TaskInstance: simulative_example_basic_dag.read_data_from_faker_api_and_load_to_pg.load_data_to_pg scheduled__2025-01-25T00:00:00+00:00 [queued]>
[2025-01-26T18:46:38.392+0000] {taskinstance.py:2613} INFO - Dependencies all met for dep_context=requeueable deps ti=<TaskInstance: simulative_example_basic_dag.read_data_from_faker_api_and_load_to_pg.load_data_to_pg scheduled__2025-01-25T00:00:00+00:00 [queued]>
[2025-01-26T18:46:38.394+0000] {taskinstance.py:2866} INFO - Starting attempt 1 of 1
[2025-01-26T18:46:38.415+0000] {taskinstance.py:2889} INFO - Executing <Task(_PythonDecoratedOperator): read_data_from_faker_api_and_load_to_pg.load_data_to_pg> on 2025-01-25 00:00:00+00:00
[2025-01-26T18:46:38.427+0000] {warnings.py:112} WARNING - /home/***/.local/lib/python3.12/site-packages/***/task/task_runner/standard_task_runner.py:70: DeprecationWarning: This process (pid=73) is multi-threaded, use of fork() may lead to deadlocks in the child.
  pid = os.fork()

[2025-01-26T18:46:38.433+0000] {standard_task_runner.py:72} INFO - Started process 90 to run task
[2025-01-26T18:46:38.438+0000] {standard_task_runner.py:104} INFO - Running: ['***', 'tasks', 'run', 'simulative_example_basic_dag', 'read_data_from_faker_api_and_load_to_pg.load_data_to_pg', 'scheduled__2025-01-25T00:00:00+00:00', '--job-id', '10', '--raw', '--subdir', 'DAGS_FOLDER/simulative_example_basic_dag.py', '--cfg-path', '/tmp/tmpl_arlp5t']
[2025-01-26T18:46:38.441+0000] {standard_task_runner.py:105} INFO - Job 10: Subtask read_data_from_faker_api_and_load_to_pg.load_data_to_pg
[2025-01-26T18:46:38.610+0000] {task_command.py:467} INFO - Running <TaskInstance: simulative_example_basic_dag.read_data_from_faker_api_and_load_to_pg.load_data_to_pg scheduled__2025-01-25T00:00:00+00:00 [running]> on host f0b50da05317
[2025-01-26T18:46:38.884+0000] {taskinstance.py:3132} INFO - Exporting env vars: AIRFLOW_CTX_DAG_OWNER='***' AIRFLOW_CTX_DAG_ID='simulative_example_basic_dag' AIRFLOW_CTX_TASK_ID='read_data_from_faker_api_and_load_to_pg.load_data_to_pg' AIRFLOW_CTX_EXECUTION_DATE='2025-01-25T00:00:00+00:00' AIRFLOW_CTX_TRY_NUMBER='1' AIRFLOW_CTX_DAG_RUN_ID='scheduled__2025-01-25T00:00:00+00:00'
[2025-01-26T18:46:38.893+0000] {logging_mixin.py:190} INFO - Task instance is in running state
[2025-01-26T18:46:38.897+0000] {logging_mixin.py:190} INFO -  Previous state of the Task instance: queued
[2025-01-26T18:46:38.898+0000] {logging_mixin.py:190} INFO - Current task name:read_data_from_faker_api_and_load_to_pg.load_data_to_pg state:running start_date:2025-01-26 18:46:38.382320+00:00
[2025-01-26T18:46:38.902+0000] {logging_mixin.py:190} INFO - Dag name:simulative_example_basic_dag and current dag run status:running
[2025-01-26T18:46:38.905+0000] {taskinstance.py:731} INFO - ::endgroup::
[2025-01-26T18:46:38.957+0000] {logging_mixin.py:190} INFO - None
[2025-01-26T18:46:39.010+0000] {taskinstance.py:3311} ERROR - Task failed with exception
Traceback (most recent call last):
  File "/home/airflow/.local/lib/python3.12/site-packages/airflow/models/taskinstance.py", line 767, in _execute_task
    result = _execute_callable(context=context, **execute_callable_kwargs)
             ^^^^^^^^^^^^^^^^^^^^^^^^^^^^^^^^^^^^^^^^^^^^^^^^^^^^^^^^^^^^^
  File "/home/airflow/.local/lib/python3.12/site-packages/airflow/models/taskinstance.py", line 733, in _execute_callable
    return ExecutionCallableRunner(
           ^^^^^^^^^^^^^^^^^^^^^^^^
  File "/home/airflow/.local/lib/python3.12/site-packages/airflow/utils/operator_helpers.py", line 252, in run
    return self.func(*args, **kwargs)
           ^^^^^^^^^^^^^^^^^^^^^^^^^^
  File "/home/airflow/.local/lib/python3.12/site-packages/airflow/models/baseoperator.py", line 422, in wrapper
    return func(self, *args, **kwargs)
           ^^^^^^^^^^^^^^^^^^^^^^^^^^^
  File "/home/airflow/.local/lib/python3.12/site-packages/airflow/decorators/base.py", line 266, in execute
    return_value = super().execute(context)
                   ^^^^^^^^^^^^^^^^^^^^^^^^
  File "/home/airflow/.local/lib/python3.12/site-packages/airflow/models/baseoperator.py", line 422, in wrapper
    return func(self, *args, **kwargs)
           ^^^^^^^^^^^^^^^^^^^^^^^^^^^
  File "/home/airflow/.local/lib/python3.12/site-packages/airflow/operators/python.py", line 238, in execute
    return_value = self.execute_callable()
                   ^^^^^^^^^^^^^^^^^^^^^^^
  File "/home/airflow/.local/lib/python3.12/site-packages/airflow/operators/python.py", line 256, in execute_callable
    return runner.run(*self.op_args, **self.op_kwargs)
           ^^^^^^^^^^^^^^^^^^^^^^^^^^^^^^^^^^^^^^^^^^^
  File "/home/airflow/.local/lib/python3.12/site-packages/airflow/utils/operator_helpers.py", line 252, in run
    return self.func(*args, **kwargs)
           ^^^^^^^^^^^^^^^^^^^^^^^^^^
  File "/opt/airflow/dags/simulative_example_basic_dag.py", line 45, in load_data_to_pg
    pg_conn = BaseHook.get_connection("postgres")
              ^^^^^^^^^^^^^^^^^^^^^^^^^^^^^^^^^^^
  File "/home/airflow/.local/lib/python3.12/site-packages/airflow/hooks/base.py", line 83, in get_connection
    conn = Connection.get_connection_from_secrets(conn_id)
           ^^^^^^^^^^^^^^^^^^^^^^^^^^^^^^^^^^^^^^^^^^^^^^^
  File "/home/airflow/.local/lib/python3.12/site-packages/airflow/models/connection.py", line 537, in get_connection_from_secrets
    raise AirflowNotFoundException(f"The conn_id `{conn_id}` isn't defined")
airflow.exceptions.AirflowNotFoundException: The conn_id `postgres` isn't defined
[2025-01-26T18:46:39.037+0000] {logging_mixin.py:190} INFO - Task instance in failure state
[2025-01-26T18:46:39.038+0000] {logging_mixin.py:190} INFO - Task start:2025-01-26 18:46:38.382320+00:00 end:2025-01-26 18:46:39.034667+00:00 duration:0.652347
[2025-01-26T18:46:39.040+0000] {logging_mixin.py:190} INFO - Task:<Task(_PythonDecoratedOperator): read_data_from_faker_api_and_load_to_pg.load_data_to_pg> dag:<DAG: simulative_example_basic_dag> dagrun:<DagRun simulative_example_basic_dag @ 2025-01-25 00:00:00+00:00: scheduled__2025-01-25T00:00:00+00:00, state:running, queued_at: 2025-01-26 18:46:33.970706+00:00. externally triggered: False>
[2025-01-26T18:46:39.040+0000] {logging_mixin.py:190} INFO - Failure caused by The conn_id `postgres` isn't defined
[2025-01-26T18:46:39.042+0000] {taskinstance.py:1225} INFO - Marking task as FAILED. dag_id=simulative_example_basic_dag, task_id=read_data_from_faker_api_and_load_to_pg.load_data_to_pg, run_id=scheduled__2025-01-25T00:00:00+00:00, execution_date=20250125T000000, start_date=20250126T184638, end_date=20250126T184639
[2025-01-26T18:46:39.110+0000] {taskinstance.py:340} INFO - ::group::Post task execution logs
[2025-01-26T18:46:39.119+0000] {standard_task_runner.py:124} ERROR - Failed to execute job 10 for task read_data_from_faker_api_and_load_to_pg.load_data_to_pg (The conn_id `postgres` isn't defined; 90)
Traceback (most recent call last):
  File "/home/airflow/.local/lib/python3.12/site-packages/airflow/task/task_runner/standard_task_runner.py", line 117, in _start_by_fork
    ret = args.func(args, dag=self.dag)
          ^^^^^^^^^^^^^^^^^^^^^^^^^^^^^
  File "/home/airflow/.local/lib/python3.12/site-packages/airflow/cli/cli_config.py", line 49, in command
    return func(*args, **kwargs)
           ^^^^^^^^^^^^^^^^^^^^^
  File "/home/airflow/.local/lib/python3.12/site-packages/airflow/utils/cli.py", line 116, in wrapper
    return f(*args, **kwargs)
           ^^^^^^^^^^^^^^^^^^
  File "/home/airflow/.local/lib/python3.12/site-packages/airflow/cli/commands/task_command.py", line 483, in task_run
    task_return_code = _run_task_by_selected_method(args, _dag, ti)
                       ^^^^^^^^^^^^^^^^^^^^^^^^^^^^^^^^^^^^^^^^^^^^
  File "/home/airflow/.local/lib/python3.12/site-packages/airflow/cli/commands/task_command.py", line 256, in _run_task_by_selected_method
    return _run_raw_task(args, ti)
           ^^^^^^^^^^^^^^^^^^^^^^^
  File "/home/airflow/.local/lib/python3.12/site-packages/airflow/cli/commands/task_command.py", line 341, in _run_raw_task
    return ti._run_raw_task(
           ^^^^^^^^^^^^^^^^^
  File "/home/airflow/.local/lib/python3.12/site-packages/airflow/utils/session.py", line 97, in wrapper
    return func(*args, session=session, **kwargs)
           ^^^^^^^^^^^^^^^^^^^^^^^^^^^^^^^^^^^^^^
  File "/home/airflow/.local/lib/python3.12/site-packages/airflow/models/taskinstance.py", line 3005, in _run_raw_task
    return _run_raw_task(
           ^^^^^^^^^^^^^^
  File "/home/airflow/.local/lib/python3.12/site-packages/airflow/models/taskinstance.py", line 273, in _run_raw_task
    TaskInstance._execute_task_with_callbacks(
  File "/home/airflow/.local/lib/python3.12/site-packages/airflow/models/taskinstance.py", line 3159, in _execute_task_with_callbacks
    result = self._execute_task(context, task_orig)
             ^^^^^^^^^^^^^^^^^^^^^^^^^^^^^^^^^^^^^^
  File "/home/airflow/.local/lib/python3.12/site-packages/airflow/models/taskinstance.py", line 3183, in _execute_task
    return _execute_task(self, context, task_orig)
           ^^^^^^^^^^^^^^^^^^^^^^^^^^^^^^^^^^^^^^^
  File "/home/airflow/.local/lib/python3.12/site-packages/airflow/models/taskinstance.py", line 767, in _execute_task
    result = _execute_callable(context=context, **execute_callable_kwargs)
             ^^^^^^^^^^^^^^^^^^^^^^^^^^^^^^^^^^^^^^^^^^^^^^^^^^^^^^^^^^^^^
  File "/home/airflow/.local/lib/python3.12/site-packages/airflow/models/taskinstance.py", line 733, in _execute_callable
    return ExecutionCallableRunner(
           ^^^^^^^^^^^^^^^^^^^^^^^^
  File "/home/airflow/.local/lib/python3.12/site-packages/airflow/utils/operator_helpers.py", line 252, in run
    return self.func(*args, **kwargs)
           ^^^^^^^^^^^^^^^^^^^^^^^^^^
  File "/home/airflow/.local/lib/python3.12/site-packages/airflow/models/baseoperator.py", line 422, in wrapper
    return func(self, *args, **kwargs)
           ^^^^^^^^^^^^^^^^^^^^^^^^^^^
  File "/home/airflow/.local/lib/python3.12/site-packages/airflow/decorators/base.py", line 266, in execute
    return_value = super().execute(context)
                   ^^^^^^^^^^^^^^^^^^^^^^^^
  File "/home/airflow/.local/lib/python3.12/site-packages/airflow/models/baseoperator.py", line 422, in wrapper
    return func(self, *args, **kwargs)
           ^^^^^^^^^^^^^^^^^^^^^^^^^^^
  File "/home/airflow/.local/lib/python3.12/site-packages/airflow/operators/python.py", line 238, in execute
    return_value = self.execute_callable()
                   ^^^^^^^^^^^^^^^^^^^^^^^
  File "/home/airflow/.local/lib/python3.12/site-packages/airflow/operators/python.py", line 256, in execute_callable
    return runner.run(*self.op_args, **self.op_kwargs)
           ^^^^^^^^^^^^^^^^^^^^^^^^^^^^^^^^^^^^^^^^^^^
  File "/home/airflow/.local/lib/python3.12/site-packages/airflow/utils/operator_helpers.py", line 252, in run
    return self.func(*args, **kwargs)
           ^^^^^^^^^^^^^^^^^^^^^^^^^^
  File "/opt/airflow/dags/simulative_example_basic_dag.py", line 45, in load_data_to_pg
    pg_conn = BaseHook.get_connection("postgres")
              ^^^^^^^^^^^^^^^^^^^^^^^^^^^^^^^^^^^
  File "/home/airflow/.local/lib/python3.12/site-packages/airflow/hooks/base.py", line 83, in get_connection
    conn = Connection.get_connection_from_secrets(conn_id)
           ^^^^^^^^^^^^^^^^^^^^^^^^^^^^^^^^^^^^^^^^^^^^^^^
  File "/home/airflow/.local/lib/python3.12/site-packages/airflow/models/connection.py", line 537, in get_connection_from_secrets
    raise AirflowNotFoundException(f"The conn_id `{conn_id}` isn't defined")
airflow.exceptions.AirflowNotFoundException: The conn_id `postgres` isn't defined
[2025-01-26T18:46:39.209+0000] {local_task_job_runner.py:266} INFO - Task exited with return code 1
[2025-01-26T18:46:39.326+0000] {taskinstance.py:3895} INFO - 0 downstream tasks scheduled from follow-on schedule check
[2025-01-26T18:46:39.328+0000] {local_task_job_runner.py:245} INFO - ::endgroup::
[2025-01-26T18:52:12.664+0000] {local_task_job_runner.py:123} INFO - ::group::Pre task execution logs
[2025-01-26T18:52:12.674+0000] {taskinstance.py:2613} INFO - Dependencies all met for dep_context=non-requeueable deps ti=<TaskInstance: simulative_example_basic_dag.read_data_from_faker_api_and_load_to_pg.load_data_to_pg scheduled__2025-01-25T00:00:00+00:00 [queued]>
[2025-01-26T18:52:12.681+0000] {taskinstance.py:2613} INFO - Dependencies all met for dep_context=requeueable deps ti=<TaskInstance: simulative_example_basic_dag.read_data_from_faker_api_and_load_to_pg.load_data_to_pg scheduled__2025-01-25T00:00:00+00:00 [queued]>
[2025-01-26T18:52:12.681+0000] {taskinstance.py:2866} INFO - Starting attempt 1 of 1
[2025-01-26T18:52:12.691+0000] {taskinstance.py:2889} INFO - Executing <Task(_PythonDecoratedOperator): read_data_from_faker_api_and_load_to_pg.load_data_to_pg> on 2025-01-25 00:00:00+00:00
[2025-01-26T18:52:12.695+0000] {warnings.py:112} WARNING - /home/***/.local/lib/python3.12/site-packages/***/task/task_runner/standard_task_runner.py:70: DeprecationWarning: This process (pid=69) is multi-threaded, use of fork() may lead to deadlocks in the child.
  pid = os.fork()

[2025-01-26T18:52:12.697+0000] {standard_task_runner.py:72} INFO - Started process 84 to run task
[2025-01-26T18:52:12.697+0000] {standard_task_runner.py:104} INFO - Running: ['***', 'tasks', 'run', 'simulative_example_basic_dag', 'read_data_from_faker_api_and_load_to_pg.load_data_to_pg', 'scheduled__2025-01-25T00:00:00+00:00', '--job-id', '5', '--raw', '--subdir', 'DAGS_FOLDER/simulative_example_basic_dag.py', '--cfg-path', '/tmp/tmplbwdazlk']
[2025-01-26T18:52:12.699+0000] {standard_task_runner.py:105} INFO - Job 5: Subtask read_data_from_faker_api_and_load_to_pg.load_data_to_pg
[2025-01-26T18:52:12.733+0000] {task_command.py:467} INFO - Running <TaskInstance: simulative_example_basic_dag.read_data_from_faker_api_and_load_to_pg.load_data_to_pg scheduled__2025-01-25T00:00:00+00:00 [running]> on host 7f022d612633
[2025-01-26T18:52:13.201+0000] {taskinstance.py:3132} INFO - Exporting env vars: AIRFLOW_CTX_DAG_OWNER='***' AIRFLOW_CTX_DAG_ID='simulative_example_basic_dag' AIRFLOW_CTX_TASK_ID='read_data_from_faker_api_and_load_to_pg.load_data_to_pg' AIRFLOW_CTX_EXECUTION_DATE='2025-01-25T00:00:00+00:00' AIRFLOW_CTX_TRY_NUMBER='1' AIRFLOW_CTX_DAG_RUN_ID='scheduled__2025-01-25T00:00:00+00:00'
[2025-01-26T18:52:13.201+0000] {logging_mixin.py:190} INFO - Task instance is in running state
[2025-01-26T18:52:13.202+0000] {logging_mixin.py:190} INFO -  Previous state of the Task instance: queued
[2025-01-26T18:52:13.202+0000] {logging_mixin.py:190} INFO - Current task name:read_data_from_faker_api_and_load_to_pg.load_data_to_pg state:running start_date:2025-01-26 18:52:12.676110+00:00
[2025-01-26T18:52:13.203+0000] {logging_mixin.py:190} INFO - Dag name:simulative_example_basic_dag and current dag run status:running
[2025-01-26T18:52:13.203+0000] {taskinstance.py:731} INFO - ::endgroup::
[2025-01-26T18:52:13.214+0000] {logging_mixin.py:190} INFO - None
[2025-01-26T18:52:13.215+0000] {connection.py:531} ERROR - Unable to retrieve connection from secrets backend (LocalFilesystemBackend). Checking subsequent secrets backend.
Traceback (most recent call last):
  File "/home/airflow/.local/lib/python3.12/site-packages/airflow/models/connection.py", line 526, in get_connection_from_secrets
    conn = secrets_backend.get_connection(conn_id=conn_id)
           ^^^^^^^^^^^^^^^^^^^^^^^^^^^^^^^^^^^^^^^^^^^^^^^
  File "/home/airflow/.local/lib/python3.12/site-packages/airflow/secrets/local_filesystem.py", line 317, in get_connection
    if conn_id in self._local_connections:
                  ^^^^^^^^^^^^^^^^^^^^^^^
  File "/home/airflow/.local/lib/python3.12/site-packages/airflow/secrets/local_filesystem.py", line 314, in _local_connections
    return load_connections_dict(self.connections_file)
           ^^^^^^^^^^^^^^^^^^^^^^^^^^^^^^^^^^^^^^^^^^^^
  File "/home/airflow/.local/lib/python3.12/site-packages/airflow/secrets/local_filesystem.py", line 266, in load_connections_dict
    secrets: dict[str, Any] = _parse_secret_file(file_path)
                              ^^^^^^^^^^^^^^^^^^^^^^^^^^^^^
  File "/home/airflow/.local/lib/python3.12/site-packages/airflow/secrets/local_filesystem.py", line 163, in _parse_secret_file
    raise AirflowException(
airflow.exceptions.AirflowException: File /opt/***/data/connections.yml was not found. Check the configuration of your Secrets backend.
[2025-01-26T18:52:13.228+0000] {taskinstance.py:3311} ERROR - Task failed with exception
Traceback (most recent call last):
  File "/home/airflow/.local/lib/python3.12/site-packages/airflow/models/taskinstance.py", line 767, in _execute_task
    result = _execute_callable(context=context, **execute_callable_kwargs)
             ^^^^^^^^^^^^^^^^^^^^^^^^^^^^^^^^^^^^^^^^^^^^^^^^^^^^^^^^^^^^^
  File "/home/airflow/.local/lib/python3.12/site-packages/airflow/models/taskinstance.py", line 733, in _execute_callable
    return ExecutionCallableRunner(
           ^^^^^^^^^^^^^^^^^^^^^^^^
  File "/home/airflow/.local/lib/python3.12/site-packages/airflow/utils/operator_helpers.py", line 252, in run
    return self.func(*args, **kwargs)
           ^^^^^^^^^^^^^^^^^^^^^^^^^^
  File "/home/airflow/.local/lib/python3.12/site-packages/airflow/models/baseoperator.py", line 422, in wrapper
    return func(self, *args, **kwargs)
           ^^^^^^^^^^^^^^^^^^^^^^^^^^^
  File "/home/airflow/.local/lib/python3.12/site-packages/airflow/decorators/base.py", line 266, in execute
    return_value = super().execute(context)
                   ^^^^^^^^^^^^^^^^^^^^^^^^
  File "/home/airflow/.local/lib/python3.12/site-packages/airflow/models/baseoperator.py", line 422, in wrapper
    return func(self, *args, **kwargs)
           ^^^^^^^^^^^^^^^^^^^^^^^^^^^
  File "/home/airflow/.local/lib/python3.12/site-packages/airflow/operators/python.py", line 238, in execute
    return_value = self.execute_callable()
                   ^^^^^^^^^^^^^^^^^^^^^^^
  File "/home/airflow/.local/lib/python3.12/site-packages/airflow/operators/python.py", line 256, in execute_callable
    return runner.run(*self.op_args, **self.op_kwargs)
           ^^^^^^^^^^^^^^^^^^^^^^^^^^^^^^^^^^^^^^^^^^^
  File "/home/airflow/.local/lib/python3.12/site-packages/airflow/utils/operator_helpers.py", line 252, in run
    return self.func(*args, **kwargs)
           ^^^^^^^^^^^^^^^^^^^^^^^^^^
  File "/opt/airflow/dags/simulative_example_basic_dag.py", line 45, in load_data_to_pg
    pg_conn = BaseHook.get_connection("postgres")
              ^^^^^^^^^^^^^^^^^^^^^^^^^^^^^^^^^^^
  File "/home/airflow/.local/lib/python3.12/site-packages/airflow/hooks/base.py", line 83, in get_connection
    conn = Connection.get_connection_from_secrets(conn_id)
           ^^^^^^^^^^^^^^^^^^^^^^^^^^^^^^^^^^^^^^^^^^^^^^^
  File "/home/airflow/.local/lib/python3.12/site-packages/airflow/models/connection.py", line 537, in get_connection_from_secrets
    raise AirflowNotFoundException(f"The conn_id `{conn_id}` isn't defined")
airflow.exceptions.AirflowNotFoundException: The conn_id `postgres` isn't defined
[2025-01-26T18:52:13.232+0000] {logging_mixin.py:190} INFO - Task instance in failure state
[2025-01-26T18:52:13.235+0000] {logging_mixin.py:190} INFO - Task start:2025-01-26 18:52:12.676110+00:00 end:2025-01-26 18:52:13.231635+00:00 duration:0.555525
[2025-01-26T18:52:13.236+0000] {logging_mixin.py:190} INFO - Task:<Task(_PythonDecoratedOperator): read_data_from_faker_api_and_load_to_pg.load_data_to_pg> dag:<DAG: simulative_example_basic_dag> dagrun:<DagRun simulative_example_basic_dag @ 2025-01-25 00:00:00+00:00: scheduled__2025-01-25T00:00:00+00:00, state:running, queued_at: 2025-01-26 18:52:09.254469+00:00. externally triggered: False>
[2025-01-26T18:52:13.237+0000] {logging_mixin.py:190} INFO - Failure caused by The conn_id `postgres` isn't defined
[2025-01-26T18:52:13.237+0000] {taskinstance.py:1225} INFO - Marking task as FAILED. dag_id=simulative_example_basic_dag, task_id=read_data_from_faker_api_and_load_to_pg.load_data_to_pg, run_id=scheduled__2025-01-25T00:00:00+00:00, execution_date=20250125T000000, start_date=20250126T185212, end_date=20250126T185213
[2025-01-26T18:52:13.254+0000] {taskinstance.py:340} INFO - ::group::Post task execution logs
[2025-01-26T18:52:13.255+0000] {standard_task_runner.py:124} ERROR - Failed to execute job 5 for task read_data_from_faker_api_and_load_to_pg.load_data_to_pg (The conn_id `postgres` isn't defined; 84)
Traceback (most recent call last):
  File "/home/airflow/.local/lib/python3.12/site-packages/airflow/task/task_runner/standard_task_runner.py", line 117, in _start_by_fork
    ret = args.func(args, dag=self.dag)
          ^^^^^^^^^^^^^^^^^^^^^^^^^^^^^
  File "/home/airflow/.local/lib/python3.12/site-packages/airflow/cli/cli_config.py", line 49, in command
    return func(*args, **kwargs)
           ^^^^^^^^^^^^^^^^^^^^^
  File "/home/airflow/.local/lib/python3.12/site-packages/airflow/utils/cli.py", line 116, in wrapper
    return f(*args, **kwargs)
           ^^^^^^^^^^^^^^^^^^
  File "/home/airflow/.local/lib/python3.12/site-packages/airflow/cli/commands/task_command.py", line 483, in task_run
    task_return_code = _run_task_by_selected_method(args, _dag, ti)
                       ^^^^^^^^^^^^^^^^^^^^^^^^^^^^^^^^^^^^^^^^^^^^
  File "/home/airflow/.local/lib/python3.12/site-packages/airflow/cli/commands/task_command.py", line 256, in _run_task_by_selected_method
    return _run_raw_task(args, ti)
           ^^^^^^^^^^^^^^^^^^^^^^^
  File "/home/airflow/.local/lib/python3.12/site-packages/airflow/cli/commands/task_command.py", line 341, in _run_raw_task
    return ti._run_raw_task(
           ^^^^^^^^^^^^^^^^^
  File "/home/airflow/.local/lib/python3.12/site-packages/airflow/utils/session.py", line 97, in wrapper
    return func(*args, session=session, **kwargs)
           ^^^^^^^^^^^^^^^^^^^^^^^^^^^^^^^^^^^^^^
  File "/home/airflow/.local/lib/python3.12/site-packages/airflow/models/taskinstance.py", line 3005, in _run_raw_task
    return _run_raw_task(
           ^^^^^^^^^^^^^^
  File "/home/airflow/.local/lib/python3.12/site-packages/airflow/models/taskinstance.py", line 273, in _run_raw_task
    TaskInstance._execute_task_with_callbacks(
  File "/home/airflow/.local/lib/python3.12/site-packages/airflow/models/taskinstance.py", line 3159, in _execute_task_with_callbacks
    result = self._execute_task(context, task_orig)
             ^^^^^^^^^^^^^^^^^^^^^^^^^^^^^^^^^^^^^^
  File "/home/airflow/.local/lib/python3.12/site-packages/airflow/models/taskinstance.py", line 3183, in _execute_task
    return _execute_task(self, context, task_orig)
           ^^^^^^^^^^^^^^^^^^^^^^^^^^^^^^^^^^^^^^^
  File "/home/airflow/.local/lib/python3.12/site-packages/airflow/models/taskinstance.py", line 767, in _execute_task
    result = _execute_callable(context=context, **execute_callable_kwargs)
             ^^^^^^^^^^^^^^^^^^^^^^^^^^^^^^^^^^^^^^^^^^^^^^^^^^^^^^^^^^^^^
  File "/home/airflow/.local/lib/python3.12/site-packages/airflow/models/taskinstance.py", line 733, in _execute_callable
    return ExecutionCallableRunner(
           ^^^^^^^^^^^^^^^^^^^^^^^^
  File "/home/airflow/.local/lib/python3.12/site-packages/airflow/utils/operator_helpers.py", line 252, in run
    return self.func(*args, **kwargs)
           ^^^^^^^^^^^^^^^^^^^^^^^^^^
  File "/home/airflow/.local/lib/python3.12/site-packages/airflow/models/baseoperator.py", line 422, in wrapper
    return func(self, *args, **kwargs)
           ^^^^^^^^^^^^^^^^^^^^^^^^^^^
  File "/home/airflow/.local/lib/python3.12/site-packages/airflow/decorators/base.py", line 266, in execute
    return_value = super().execute(context)
                   ^^^^^^^^^^^^^^^^^^^^^^^^
  File "/home/airflow/.local/lib/python3.12/site-packages/airflow/models/baseoperator.py", line 422, in wrapper
    return func(self, *args, **kwargs)
           ^^^^^^^^^^^^^^^^^^^^^^^^^^^
  File "/home/airflow/.local/lib/python3.12/site-packages/airflow/operators/python.py", line 238, in execute
    return_value = self.execute_callable()
                   ^^^^^^^^^^^^^^^^^^^^^^^
  File "/home/airflow/.local/lib/python3.12/site-packages/airflow/operators/python.py", line 256, in execute_callable
    return runner.run(*self.op_args, **self.op_kwargs)
           ^^^^^^^^^^^^^^^^^^^^^^^^^^^^^^^^^^^^^^^^^^^
  File "/home/airflow/.local/lib/python3.12/site-packages/airflow/utils/operator_helpers.py", line 252, in run
    return self.func(*args, **kwargs)
           ^^^^^^^^^^^^^^^^^^^^^^^^^^
  File "/opt/airflow/dags/simulative_example_basic_dag.py", line 45, in load_data_to_pg
    pg_conn = BaseHook.get_connection("postgres")
              ^^^^^^^^^^^^^^^^^^^^^^^^^^^^^^^^^^^
  File "/home/airflow/.local/lib/python3.12/site-packages/airflow/hooks/base.py", line 83, in get_connection
    conn = Connection.get_connection_from_secrets(conn_id)
           ^^^^^^^^^^^^^^^^^^^^^^^^^^^^^^^^^^^^^^^^^^^^^^^
  File "/home/airflow/.local/lib/python3.12/site-packages/airflow/models/connection.py", line 537, in get_connection_from_secrets
    raise AirflowNotFoundException(f"The conn_id `{conn_id}` isn't defined")
airflow.exceptions.AirflowNotFoundException: The conn_id `postgres` isn't defined
[2025-01-26T18:52:13.290+0000] {local_task_job_runner.py:266} INFO - Task exited with return code 1
[2025-01-26T18:52:13.318+0000] {taskinstance.py:3895} INFO - 0 downstream tasks scheduled from follow-on schedule check
[2025-01-26T18:52:13.320+0000] {local_task_job_runner.py:245} INFO - ::endgroup::
[2025-01-26T18:53:58.825+0000] {local_task_job_runner.py:123} INFO - ::group::Pre task execution logs
[2025-01-26T18:53:58.833+0000] {taskinstance.py:2613} INFO - Dependencies all met for dep_context=non-requeueable deps ti=<TaskInstance: simulative_example_basic_dag.read_data_from_faker_api_and_load_to_pg.load_data_to_pg scheduled__2025-01-25T00:00:00+00:00 [queued]>
[2025-01-26T18:53:58.838+0000] {taskinstance.py:2613} INFO - Dependencies all met for dep_context=requeueable deps ti=<TaskInstance: simulative_example_basic_dag.read_data_from_faker_api_and_load_to_pg.load_data_to_pg scheduled__2025-01-25T00:00:00+00:00 [queued]>
[2025-01-26T18:53:58.838+0000] {taskinstance.py:2866} INFO - Starting attempt 1 of 1
[2025-01-26T18:53:58.844+0000] {taskinstance.py:2889} INFO - Executing <Task(_PythonDecoratedOperator): read_data_from_faker_api_and_load_to_pg.load_data_to_pg> on 2025-01-25 00:00:00+00:00
[2025-01-26T18:53:58.850+0000] {warnings.py:112} WARNING - /home/***/.local/lib/python3.12/site-packages/***/task/task_runner/standard_task_runner.py:70: DeprecationWarning: This process (pid=69) is multi-threaded, use of fork() may lead to deadlocks in the child.
  pid = os.fork()

[2025-01-26T18:53:58.851+0000] {standard_task_runner.py:72} INFO - Started process 74 to run task
[2025-01-26T18:53:58.853+0000] {standard_task_runner.py:104} INFO - Running: ['***', 'tasks', 'run', 'simulative_example_basic_dag', 'read_data_from_faker_api_and_load_to_pg.load_data_to_pg', 'scheduled__2025-01-25T00:00:00+00:00', '--job-id', '5', '--raw', '--subdir', 'DAGS_FOLDER/simulative_example_basic_dag.py', '--cfg-path', '/tmp/tmpd9f6mybs']
[2025-01-26T18:53:58.854+0000] {standard_task_runner.py:105} INFO - Job 5: Subtask read_data_from_faker_api_and_load_to_pg.load_data_to_pg
[2025-01-26T18:53:59.361+0000] {task_command.py:467} INFO - Running <TaskInstance: simulative_example_basic_dag.read_data_from_faker_api_and_load_to_pg.load_data_to_pg scheduled__2025-01-25T00:00:00+00:00 [running]> on host b82bd748d7ce
[2025-01-26T18:53:59.406+0000] {taskinstance.py:3132} INFO - Exporting env vars: AIRFLOW_CTX_DAG_OWNER='***' AIRFLOW_CTX_DAG_ID='simulative_example_basic_dag' AIRFLOW_CTX_TASK_ID='read_data_from_faker_api_and_load_to_pg.load_data_to_pg' AIRFLOW_CTX_EXECUTION_DATE='2025-01-25T00:00:00+00:00' AIRFLOW_CTX_TRY_NUMBER='1' AIRFLOW_CTX_DAG_RUN_ID='scheduled__2025-01-25T00:00:00+00:00'
[2025-01-26T18:53:59.406+0000] {logging_mixin.py:190} INFO - Task instance is in running state
[2025-01-26T18:53:59.407+0000] {logging_mixin.py:190} INFO -  Previous state of the Task instance: queued
[2025-01-26T18:53:59.407+0000] {logging_mixin.py:190} INFO - Current task name:read_data_from_faker_api_and_load_to_pg.load_data_to_pg state:running start_date:2025-01-26 18:53:58.834436+00:00
[2025-01-26T18:53:59.407+0000] {logging_mixin.py:190} INFO - Dag name:simulative_example_basic_dag and current dag run status:running
[2025-01-26T18:53:59.407+0000] {taskinstance.py:731} INFO - ::endgroup::
[2025-01-26T18:53:59.413+0000] {logging_mixin.py:190} INFO - None
[2025-01-26T18:53:59.414+0000] {crypto.py:82} WARNING - empty cryptography key - values will not be stored encrypted.
[2025-01-26T18:53:59.415+0000] {base.py:84} INFO - Retrieving connection 'postgres'
[2025-01-26T18:53:59.416+0000] {taskinstance.py:3311} ERROR - Task failed with exception
Traceback (most recent call last):
  File "/home/airflow/.local/lib/python3.12/site-packages/airflow/models/taskinstance.py", line 767, in _execute_task
    result = _execute_callable(context=context, **execute_callable_kwargs)
             ^^^^^^^^^^^^^^^^^^^^^^^^^^^^^^^^^^^^^^^^^^^^^^^^^^^^^^^^^^^^^
  File "/home/airflow/.local/lib/python3.12/site-packages/airflow/models/taskinstance.py", line 733, in _execute_callable
    return ExecutionCallableRunner(
           ^^^^^^^^^^^^^^^^^^^^^^^^
  File "/home/airflow/.local/lib/python3.12/site-packages/airflow/utils/operator_helpers.py", line 252, in run
    return self.func(*args, **kwargs)
           ^^^^^^^^^^^^^^^^^^^^^^^^^^
  File "/home/airflow/.local/lib/python3.12/site-packages/airflow/models/baseoperator.py", line 422, in wrapper
    return func(self, *args, **kwargs)
           ^^^^^^^^^^^^^^^^^^^^^^^^^^^
  File "/home/airflow/.local/lib/python3.12/site-packages/airflow/decorators/base.py", line 266, in execute
    return_value = super().execute(context)
                   ^^^^^^^^^^^^^^^^^^^^^^^^
  File "/home/airflow/.local/lib/python3.12/site-packages/airflow/models/baseoperator.py", line 422, in wrapper
    return func(self, *args, **kwargs)
           ^^^^^^^^^^^^^^^^^^^^^^^^^^^
  File "/home/airflow/.local/lib/python3.12/site-packages/airflow/operators/python.py", line 238, in execute
    return_value = self.execute_callable()
                   ^^^^^^^^^^^^^^^^^^^^^^^
  File "/home/airflow/.local/lib/python3.12/site-packages/airflow/operators/python.py", line 256, in execute_callable
    return runner.run(*self.op_args, **self.op_kwargs)
           ^^^^^^^^^^^^^^^^^^^^^^^^^^^^^^^^^^^^^^^^^^^
  File "/home/airflow/.local/lib/python3.12/site-packages/airflow/utils/operator_helpers.py", line 252, in run
    return self.func(*args, **kwargs)
           ^^^^^^^^^^^^^^^^^^^^^^^^^^
  File "/opt/airflow/dags/simulative_example_basic_dag.py", line 51, in load_data_to_pg
    data.to_sql("person", pg_engine, if_exists="append", index=False)
    ^^^^^^^^^^^
AttributeError: 'NoneType' object has no attribute 'to_sql'
[2025-01-26T18:53:59.429+0000] {logging_mixin.py:190} INFO - Task instance in failure state
[2025-01-26T18:53:59.429+0000] {logging_mixin.py:190} INFO - Task start:2025-01-26 18:53:58.834436+00:00 end:2025-01-26 18:53:59.429430+00:00 duration:0.594994
[2025-01-26T18:53:59.430+0000] {logging_mixin.py:190} INFO - Task:<Task(_PythonDecoratedOperator): read_data_from_faker_api_and_load_to_pg.load_data_to_pg> dag:<DAG: simulative_example_basic_dag> dagrun:<DagRun simulative_example_basic_dag @ 2025-01-25 00:00:00+00:00: scheduled__2025-01-25T00:00:00+00:00, state:running, queued_at: 2025-01-26 18:53:55.413788+00:00. externally triggered: False>
[2025-01-26T18:53:59.430+0000] {logging_mixin.py:190} INFO - Failure caused by 'NoneType' object has no attribute 'to_sql'
[2025-01-26T18:53:59.430+0000] {taskinstance.py:1225} INFO - Marking task as FAILED. dag_id=simulative_example_basic_dag, task_id=read_data_from_faker_api_and_load_to_pg.load_data_to_pg, run_id=scheduled__2025-01-25T00:00:00+00:00, execution_date=20250125T000000, start_date=20250126T185358, end_date=20250126T185359
[2025-01-26T18:53:59.436+0000] {taskinstance.py:340} INFO - ::group::Post task execution logs
[2025-01-26T18:53:59.437+0000] {standard_task_runner.py:124} ERROR - Failed to execute job 5 for task read_data_from_faker_api_and_load_to_pg.load_data_to_pg ('NoneType' object has no attribute 'to_sql'; 74)
Traceback (most recent call last):
  File "/home/airflow/.local/lib/python3.12/site-packages/airflow/task/task_runner/standard_task_runner.py", line 117, in _start_by_fork
    ret = args.func(args, dag=self.dag)
          ^^^^^^^^^^^^^^^^^^^^^^^^^^^^^
  File "/home/airflow/.local/lib/python3.12/site-packages/airflow/cli/cli_config.py", line 49, in command
    return func(*args, **kwargs)
           ^^^^^^^^^^^^^^^^^^^^^
  File "/home/airflow/.local/lib/python3.12/site-packages/airflow/utils/cli.py", line 116, in wrapper
    return f(*args, **kwargs)
           ^^^^^^^^^^^^^^^^^^
  File "/home/airflow/.local/lib/python3.12/site-packages/airflow/cli/commands/task_command.py", line 483, in task_run
    task_return_code = _run_task_by_selected_method(args, _dag, ti)
                       ^^^^^^^^^^^^^^^^^^^^^^^^^^^^^^^^^^^^^^^^^^^^
  File "/home/airflow/.local/lib/python3.12/site-packages/airflow/cli/commands/task_command.py", line 256, in _run_task_by_selected_method
    return _run_raw_task(args, ti)
           ^^^^^^^^^^^^^^^^^^^^^^^
  File "/home/airflow/.local/lib/python3.12/site-packages/airflow/cli/commands/task_command.py", line 341, in _run_raw_task
    return ti._run_raw_task(
           ^^^^^^^^^^^^^^^^^
  File "/home/airflow/.local/lib/python3.12/site-packages/airflow/utils/session.py", line 97, in wrapper
    return func(*args, session=session, **kwargs)
           ^^^^^^^^^^^^^^^^^^^^^^^^^^^^^^^^^^^^^^
  File "/home/airflow/.local/lib/python3.12/site-packages/airflow/models/taskinstance.py", line 3005, in _run_raw_task
    return _run_raw_task(
           ^^^^^^^^^^^^^^
  File "/home/airflow/.local/lib/python3.12/site-packages/airflow/models/taskinstance.py", line 273, in _run_raw_task
    TaskInstance._execute_task_with_callbacks(
  File "/home/airflow/.local/lib/python3.12/site-packages/airflow/models/taskinstance.py", line 3159, in _execute_task_with_callbacks
    result = self._execute_task(context, task_orig)
             ^^^^^^^^^^^^^^^^^^^^^^^^^^^^^^^^^^^^^^
  File "/home/airflow/.local/lib/python3.12/site-packages/airflow/models/taskinstance.py", line 3183, in _execute_task
    return _execute_task(self, context, task_orig)
           ^^^^^^^^^^^^^^^^^^^^^^^^^^^^^^^^^^^^^^^
  File "/home/airflow/.local/lib/python3.12/site-packages/airflow/models/taskinstance.py", line 767, in _execute_task
    result = _execute_callable(context=context, **execute_callable_kwargs)
             ^^^^^^^^^^^^^^^^^^^^^^^^^^^^^^^^^^^^^^^^^^^^^^^^^^^^^^^^^^^^^
  File "/home/airflow/.local/lib/python3.12/site-packages/airflow/models/taskinstance.py", line 733, in _execute_callable
    return ExecutionCallableRunner(
           ^^^^^^^^^^^^^^^^^^^^^^^^
  File "/home/airflow/.local/lib/python3.12/site-packages/airflow/utils/operator_helpers.py", line 252, in run
    return self.func(*args, **kwargs)
           ^^^^^^^^^^^^^^^^^^^^^^^^^^
  File "/home/airflow/.local/lib/python3.12/site-packages/airflow/models/baseoperator.py", line 422, in wrapper
    return func(self, *args, **kwargs)
           ^^^^^^^^^^^^^^^^^^^^^^^^^^^
  File "/home/airflow/.local/lib/python3.12/site-packages/airflow/decorators/base.py", line 266, in execute
    return_value = super().execute(context)
                   ^^^^^^^^^^^^^^^^^^^^^^^^
  File "/home/airflow/.local/lib/python3.12/site-packages/airflow/models/baseoperator.py", line 422, in wrapper
    return func(self, *args, **kwargs)
           ^^^^^^^^^^^^^^^^^^^^^^^^^^^
  File "/home/airflow/.local/lib/python3.12/site-packages/airflow/operators/python.py", line 238, in execute
    return_value = self.execute_callable()
                   ^^^^^^^^^^^^^^^^^^^^^^^
  File "/home/airflow/.local/lib/python3.12/site-packages/airflow/operators/python.py", line 256, in execute_callable
    return runner.run(*self.op_args, **self.op_kwargs)
           ^^^^^^^^^^^^^^^^^^^^^^^^^^^^^^^^^^^^^^^^^^^
  File "/home/airflow/.local/lib/python3.12/site-packages/airflow/utils/operator_helpers.py", line 252, in run
    return self.func(*args, **kwargs)
           ^^^^^^^^^^^^^^^^^^^^^^^^^^
  File "/opt/airflow/dags/simulative_example_basic_dag.py", line 51, in load_data_to_pg
    data.to_sql("person", pg_engine, if_exists="append", index=False)
    ^^^^^^^^^^^
AttributeError: 'NoneType' object has no attribute 'to_sql'
[2025-01-26T18:53:59.481+0000] {local_task_job_runner.py:266} INFO - Task exited with return code 1
[2025-01-26T18:53:59.646+0000] {taskinstance.py:3895} INFO - 0 downstream tasks scheduled from follow-on schedule check
[2025-01-26T18:53:59.649+0000] {local_task_job_runner.py:245} INFO - ::endgroup::
